<?xml version="1.0" ?>
<!-- =================================================================================== -->
<!-- |    This document was autogenerated by xacro from /home/mfallon/otherprojects/thor_mang_common/src/thor_mang_common/thor_mang_description/robots/thor_mang_tud.urdf.xacro | -->
<!-- |    EDITING THIS FILE BY HAND IS NOT RECOMMENDED                                 | -->
<!-- =================================================================================== -->
<robot name="thor_mang_robot" xmlns:xacro="http://www.ros.org/wiki/xacro">
  <link name="pelvis">
<inertial>
<origin rpy="0 0 0" xyz="-0.0264 0.0 0.0162"/>
<mass value="8.2"/>
<origin xyz="0 0 0"/>
<inertia ixx="0.0341666666667" ixy="0.0" ixz="0.0" iyy="0.0341666666667" iyz="0.0" izz="0.0546666666667"/>
</inertial>
<visual>
<origin rpy=" 1.57079632679 0 1.57079632679" xyz="0.0 0 -0.0"/>
<geometry>
        <mesh filename="package://thor_mang_description/meshes/simple/pelvis.stl" scale="0.001 0.001 0.001"/>
</geometry>
<material name="blue">
  <color rgba="0.2 0.2 0.2 1"/>
</material>
</visual>
   <collision>
<origin rpy="0 0 0" xyz="-0.01 0 0.025"/>
<geometry>
        <box size="0.23 0.23 0.24"/>
</geometry>
</collision>
 </link>
  <joint name="waist_pan" type="revolute">
<origin rpy="0 0 0" xyz="0.0 0 0.137"/>
<!--rpy="0.000329950722368627 -3.91151844547536E-19 1.16573417585641E-15"-->
<parent link="pelvis"/>
<child link="waist"/>
<axis xyz="0 0 1"/>
<limit effort="21.142" lower="-3.14159265359" upper="4.71238898038" velocity="2.5"/>
<dynamics damping="0.1" friction="0"/>
  </joint>
  <link name="waist">
<inertial>
<origin rpy="0 0 0" xyz="0.0 0.0 0.0"/>
<mass value="0.1"/>
<inertia ixx="2.5e-05" ixy="0.0" ixz="0.0" iyy="2.5e-05" iyz="0.0" izz="2.5e-05"/>
    </inertial>
<visual>
<origin rpy=" 1.57079632679 0 1.57079632679" xyz="0 0 -0.039"/>
<geometry>
  <mesh filename="package://thor_mang_description/meshes/simple/waist.stl" scale="0.001 0.001 0.001"/>
</geometry>
<material name="blue">
  <color rgba="0.2 0.2 0.2 1"/>
</material>
</visual>
   <collision>
<origin rpy="0 0 0" xyz="0.024 0 0"/>
<geometry>
        <box size="0.03 0.08 0.03"/>
</geometry>
</collision>
 </link>
  <joint name="waist_tilt" type="revolute">
<origin rpy="0 0 0" xyz="0 0 0.0"/>
<!--rpy="0.000329950722368627 -3.91151844547536E-19 1.16573417585641E-15"-->
<parent link="waist"/>
<child link="utorso"/>
<axis xyz="0 1 0"/>
<limit effort="39.131" lower="-1.57079632679" upper="1.57079632679" velocity="2.5"/>
<dynamics damping="0.1" friction="0"/>
  </joint>
  <link name="utorso">
<inertial>
<origin rpy="0 0 0" xyz="-0.0264 0.0 0.155"/>
<mass value="9.21"/>
<origin xyz="0 0 0"/>
<inertia ixx="0.099775" ixy="0.0" ixz="0.0" iyy="0.07866875" iyz="0.0" izz="0.11704375"/>
</inertial>
<visual>
     <origin rpy=" 1.57079632679 0 1.57079632679" xyz="-0.0 0 0.159"/>
    <geometry>
  <mesh filename="package://thor_mang_description/meshes/simple/chest.stl" scale="0.001 0.001 0.001"/>
</geometry>
<material name="blue">
  <color rgba="0.2 0.2 0.2 1"/>
</material>
</visual>
   <collision>
<origin rpy="0 0 0" xyz="-0.075 0 0.11"/>
<geometry>
        <box size="0.24 0.31 0.24"/>
</geometry>
</collision>
   <collision>
<origin rpy="0 0 0" xyz="0.1 0.13 0.12"/>
<geometry>
        <cylinder length="0.23" radius="0.04"/>
</geometry>
</collision>
    <collision>
<origin rpy="0 0 0" xyz="0.1 -0.13 0.12"/>
<geometry>
        <cylinder length="0.23" radius="0.04"/>
</geometry>
</collision>
  </link>
  <transmission name="waist_pan_transmssion">
<type>transmission_interface/SimpleTransmission</type>
    <joint name="waist_pan">
<hardwareInterface>EffortJointInterface</hardwareInterface>
    </joint>
<actuator name="waist_pan_motor">
<hardwareInterface>EffortJointInterface</hardwareInterface>
      <mechanicalReduction>1</mechanicalReduction>
</actuator>
  </transmission>
  <gazebo reference="waist_pan">
<implicitSpringDamper>1</implicitSpringDamper>
  </gazebo>
  <transmission name="waist_tilt_transmssion">
<type>transmission_interface/SimpleTransmission</type>
    <joint name="waist_tilt">
<hardwareInterface>EffortJointInterface</hardwareInterface>
    </joint>
<actuator name="waist_tilt_motor">
<hardwareInterface>EffortJointInterface</hardwareInterface>
      <mechanicalReduction>1</mechanicalReduction>
</actuator>
  </transmission>
  <gazebo reference="waist_tilt">
<implicitSpringDamper>1</implicitSpringDamper>
  </gazebo>
  <gazebo>
<plugin filename="libhector_gazebo_ros_imu.so" name="pelvis_imu_controller">
<alwaysOn>true</alwaysOn>
<updateRate>125.0</updateRate>
      <bodyName>pelvis</bodyName>
<topicName>/thor_mang/pelvis_imu</topicName>
      <accelDrift>0.0 0.0 0.0</accelDrift>
<accelGaussianNoise>0.1 0.1 0.1</accelGaussianNoise>
      <rateDrift>0.0 0.0 0.0</rateDrift>
<rateGaussianNoise>0.05 0.05 0.05</rateGaussianNoise>
      <headingDrift>0.0</headingDrift>
<headingGaussianNoise>0.05</headingGaussianNoise>
    </plugin>
  </gazebo>
  <joint name="pelvis_imu_joint" type="fixed">
    <origin rpy="0 0 0" xyz="0.05372871 0 -0.019"/>
<parent link="pelvis"/>
<child link="pelvis_imu_link"/>
  </joint>
  <link name="pelvis_imu_link">
<!--    <xacro:inertial_sphere_with_pose_macro mass="0.1" diameter="0.05">
<origin xyz="0.0 0.0 0.0" rpy="0 0 0"/>
</xacro:inertial_sphere_with_pose_macro>-->
    <!--    <visual>
<origin
  xyz="0 0 -0.039"
  rpy=" ${M_PI*0.5} 0 ${M_PI*0.5}" />
<geometry>
   <box size="0.04 0.024 0.015" />
</geometry>
<xacro:black/>
</visual>-->
  </link>
  <gazebo>
<plugin filename="libhector_gazebo_ros_imu.so" name="pelvis_imu_controller">
<alwaysOn>true</alwaysOn>
<updateRate>125.0</updateRate>
  <bodyName>pelvis_imu_link</bodyName>
<topicName>/thor_mang/pelvis_imu</topicName>
      <accelDrift>0.0 0.0 0.0</accelDrift>
<accelGaussianNoise>0.1 0.1 0.1</accelGaussianNoise>
      <rateDrift>0.0 0.0 0.0</rateDrift>
<rateGaussianNoise>0.05 0.05 0.05</rateGaussianNoise>
      <headingDrift>0.0</headingDrift>
<headingGaussianNoise>0.05</headingGaussianNoise>
    </plugin>
  </gazebo>
  <joint name="l_hip_yaw" type="revolute">
  <origin rpy="0 0 0" xyz="0.0 0.072 -0.145"/>
<parent link="pelvis"/>
<child link="l_leg_hip_yaw"/>
<axis xyz="0 0 -1"/>
<limit effort="39.131" lower="-1.57079632679" upper="1.57079632679" velocity="2.5"/>
<dynamics damping="0.1" friction="0"/>
  </joint>
  <link name="l_leg_hip_yaw">
<inertial>
<origin rpy="0 0 0" xyz="-0.0478 0.0 0.0"/>
<mass value="0.15"/>
<inertia ixx="3.75e-05" ixy="0.0" ixz="0.0" iyy="3.75e-05" iyz="0.0" izz="3.75e-05"/>
</inertial>
    <visual>
<origin rpy=" 1.57079632679 0 -1.57079632679" xyz="0.0 0 0.063"/>
<geometry>
  <mesh filename="package://thor_mang_description/meshes/simple/hip_yaw_left.stl" scale="0.001 0.001 0.001"/>
</geometry>
<material name="blue">
  <color rgba="0.2 0.2 0.2 1"/>
</material>
</visual>
   <collision>
<origin rpy="0 0 0" xyz="-0.02 0 0"/>
<geometry>
        <box size="0.16 0.08 0.08"/>
</geometry>
</collision>
 </link>
  <joint name="l_hip_roll" type="revolute">
<origin rpy="0 0 0" xyz="0 0 0"/>
<parent link="l_leg_hip_yaw"/>
<child link="l_leg_hip_roll"/>
<axis xyz="-1 0 0"/>
<limit effort="21.142" lower="-1.57079632679" upper="1.57079632679" velocity="2.5"/>
<dynamics damping="0.1" friction="0"/>
  </joint>
  <link name="l_leg_hip_roll">
<inertial>
      <origin rpy="0 0 0" xyz="-0.0216 0.0 0.0"/>
<mass value="1.02"/>
<inertia ixx="0.000255" ixy="0.0" ixz="0.0" iyy="0.000255" iyz="0.0" izz="0.000255"/>
</inertial>
<visual>
<origin rpy=" 1.57079632679 0 -1.57079632679" xyz="0.0 0 0"/>
<geometry>
  <mesh filename="package://thor_mang_description/meshes/simple/hip_roll_left.stl" scale="0.001 0.001 0.001"/>
</geometry>
<material name="blue">
  <color rgba="0.2 0.2 0.2 1"/>
</material>
</visual>
<collision>
      <origin rpy=" 3.14159265359 1.57079632679 0" xyz="-0.02 0 0"/>
  <geometry>
  <box size="0.16 0.08 0.08"/>
</geometry>
</collision>
  </link>
  <joint name="l_hip_pitch" type="revolute">
<origin rpy="0 0 0" xyz="0 0 0"/>
<!--rpy="0.000329950722368627 -3.91151844547536E-19 1.16573417585641E-15"-->
<parent link="l_leg_hip_roll"/>
<child link="l_leg_thigh"/>
<axis xyz="0 1 0"/>
<limit effort="39.131" lower="-1.57079632679" upper="1.57079632679" velocity="2.5"/>
<dynamics damping="0.1" friction="0"/>
  </joint>
  <link name="l_leg_thigh">
<inertial>
      <origin rpy="0 0 0" xyz="-0.0033 0.0294 -0.172"/>
<mass value="3.12"/>
<inertia ixx="0.00702" ixy="0.0" ixz="0.0" iyy="0.00702" iyz="0.0" izz="0.00702"/>
</inertial>
<visual>
<origin rpy=" 1.57079632679 0 1.57079632679" xyz="0 0 -0.0"/>
<geometry>
  <mesh filename="package://thor_mang_description/meshes/simple/hip_pitch_left.stl" scale="0.001 0.001  0.001"/>
</geometry>
<material name="blue">
  <color rgba="0.2 0.2 0.2 1"/>
</material>
</visual>
   <collision>
<origin rpy="0 0 0" xyz="0.01 0.025 -0.15"/>
<geometry>
        <box size="0.09 0.13 0.3"/>
</geometry>
</collision>
  <collision>
<origin rpy=" 0 0.785398163397 0" xyz="-0.03 0.025 -0.3"/>
<geometry>
  <box size="0.06 0.14 0.06"/>
</geometry>
    </collision>
  </link>
  <joint name="l_knee" type="revolute">
<origin rpy="0 0 0" xyz="-0.03 0 -0.3"/>
<!--rpy="0.000329950722368627 -3.91151844547536E-19 1.16573417585641E-15"-->
<parent link="l_leg_thigh"/>
<child link="l_leg_shank"/>
<axis xyz="0 1 0"/>
<limit effort="39.131" lower="-0.471238898038" upper="3.14159265359" velocity="2.5"/>
<dynamics damping="0.1" friction="0"/>
  </joint>
  <link name="l_leg_shank">
<inertial>
      <origin rpy="0 0 0" xyz="0.03 0.0313 -0.17"/>
<mass value="2.24"/>
<inertia ixx="0.00504" ixy="0.0" ixz="0.0" iyy="0.00504" iyz="0.0" izz="0.00504"/>
</inertial>
<visual>
<origin rpy=" 1.57079632679 0 1.57079632679" xyz="0.03 0 0"/>
<geometry>
  <mesh filename="package://thor_mang_description/meshes/simple/leg_left.stl" scale="0.001 0.001  0.001"/>
</geometry>
<material name="blue">
  <color rgba="0.2 0.2 0.2 1"/>
</material>
</visual>
<collision>
      <origin rpy="0 0 0" xyz="0.04 0.025 -0.15"/>
<geometry>
    <box size="0.09 0.13 0.3"/>
</geometry>
</collision>
  </link>
  <joint name="l_ankle_pitch" type="revolute">
<origin rpy="0 0 0" xyz="0.03 0 -0.3"/>
<!--rpy="0.000329950722368627 -3.91151844547536E-19 1.16573417585641E-15"-->
<parent link="l_leg_shank"/>
<child link="l_leg_ankle_roll"/>
    <axis xyz="0 -1.0 0"/>
<limit effort="39.131" lower="-1.82212373908" upper="1.82212373908" velocity="2.5"/>
<dynamics damping="0.1" friction="0"/>
  </joint>
  <link name="l_leg_ankle_roll">
<inertial>
<origin rpy="0 0 0" xyz="0.0 0.0 0.0"/>
<mass value="0.86"/>
<inertia ixx="0.0001376" ixy="0.0" ixz="0.0" iyy="0.0001376" iyz="0.0" izz="0.0001376"/>
</inertial>
<visual>
<origin rpy=" 1.57079632679 0 -1.57079632679" xyz="0.0 0 0"/>
<geometry>
  <mesh filename="package://thor_mang_description/meshes/simple/ankle_roll_left.stl" scale="0.001 0.001  0.001"/>
</geometry>
<material name="blue">
  <color rgba="0.2 0.2 0.2 1"/>
</material>
</visual>
<collision>
      <origin rpy="0 0 0" xyz="0 0 0"/>
<geometry>
  <box size="0.12 0.08 0.08"/>
</geometry>
</collision>
  </link>
  <joint name="l_ankle_roll" type="revolute">
<origin rpy="0 0 0" xyz="-0.0 0 0"/>
    <!--rpy="0.000329950722368627 -3.91151844547536E-19 1.16573417585641E-15"-->
<parent link="l_leg_ankle_roll"/>
<child link="l_foot"/>
    <axis xyz="1 0 0"/>
<limit effort="21.142" lower="-0.785398163397" upper="3.14159265359" velocity="2.5"/>
<dynamics damping="0.1" friction="0"/>
  </joint>
  <link name="l_foot">
<inertial>
<origin rpy="0 0 0" xyz="0.0 0.0 -0.08"/>
<mass value="1.03"/>
<inertia ixx="0.0005047" ixy="0.0" ixz="0.0" iyy="0.0005047" iyz="0.0" izz="0.0005047"/>
</inertial>
<visual>
<origin rpy=" 1.57079632679 0 -1.57079632679" xyz="0.0 0 0"/>
<geometry>
  <mesh filename="package://thor_mang_description/meshes/simple/foot_left.stl" scale="0.001 0.001  0.001"/>
</geometry>
<material name="blue">
  <color rgba="0.2 0.2 0.2 1"/>
</material>
</visual>
   <collision>
<origin rpy="0 0 0" xyz="0.009 0 -0.098"/>
<geometry>
        <box size="0.24 0.144 0.04"/>
</geometry>
</collision>
    <!--Additional collision geometry below foot to get more stable behavior in simulation-->
<!--  
<collision>
<origin rpy="0 0 0" xyz="0.017 0.0 -0.118"/>
<geometry>
  <box size="0.265 0.15 0.01"/>
      </geometry>
<xacro:red/>
</collision>
-->
  </link>
 <gazebo reference="l_foot">
<!-- kp and kd for rubber -->
<kp>1000000.0</kp>
    <kd>100.0</kd>
<mu1>1.5</mu1>
<mu2>1.5</mu2>
<fdir1>1 0 0</fdir1>
    <maxVel>1.0</maxVel>
<minDepth>0.00</minDepth>
  </gazebo>
  <transmission name="l_hip_yaw_transmssion">
<type>transmission_interface/SimpleTransmission</type>
    <joint name="l_hip_yaw">
<hardwareInterface>EffortJointInterface</hardwareInterface>
    </joint>
<actuator name="l_hip_yaw_motor">
<hardwareInterface>EffortJointInterface</hardwareInterface>
      <mechanicalReduction>1</mechanicalReduction>
</actuator>
  </transmission>
  <gazebo reference="l_hip_yaw">
<implicitSpringDamper>1</implicitSpringDamper>
  </gazebo>
  <transmission name="l_hip_roll_transmssion">
<type>transmission_interface/SimpleTransmission</type>
    <joint name="l_hip_roll">
<hardwareInterface>EffortJointInterface</hardwareInterface>
    </joint>
<actuator name="l_hip_roll_motor">
<hardwareInterface>EffortJointInterface</hardwareInterface>
      <mechanicalReduction>1</mechanicalReduction>
</actuator>
  </transmission>
  <gazebo reference="l_hip_roll">
<implicitSpringDamper>1</implicitSpringDamper>
  </gazebo>
  <transmission name="l_hip_pitch_transmssion">
<type>transmission_interface/SimpleTransmission</type>
    <joint name="l_hip_pitch">
<hardwareInterface>EffortJointInterface</hardwareInterface>
    </joint>
<actuator name="l_hip_pitch_motor">
<hardwareInterface>EffortJointInterface</hardwareInterface>
      <mechanicalReduction>1</mechanicalReduction>
</actuator>
  </transmission>
  <gazebo reference="l_hip_pitch">
<implicitSpringDamper>1</implicitSpringDamper>
  </gazebo>
  <transmission name="l_knee_transmssion">
<type>transmission_interface/SimpleTransmission</type>
    <joint name="l_knee">
<hardwareInterface>EffortJointInterface</hardwareInterface>
    </joint>
<actuator name="l_knee_motor">
<hardwareInterface>EffortJointInterface</hardwareInterface>
      <mechanicalReduction>1</mechanicalReduction>
</actuator>
  </transmission>
  <gazebo reference="l_knee">
<implicitSpringDamper>1</implicitSpringDamper>
  </gazebo>
  <transmission name="l_ankle_pitch_transmssion">
<type>transmission_interface/SimpleTransmission</type>
    <joint name="l_ankle_pitch">
<hardwareInterface>EffortJointInterface</hardwareInterface>
    </joint>
<actuator name="l_ankle_pitch_motor">
<hardwareInterface>EffortJointInterface</hardwareInterface>
      <mechanicalReduction>1</mechanicalReduction>
</actuator>
  </transmission>
  <gazebo reference="l_ankle_pitch">
<implicitSpringDamper>1</implicitSpringDamper>
  </gazebo>
  <transmission name="l_ankle_roll_transmssion">
<type>transmission_interface/SimpleTransmission</type>
    <joint name="l_ankle_roll">
<hardwareInterface>EffortJointInterface</hardwareInterface>
    </joint>
<actuator name="l_ankle_roll_motor">
<hardwareInterface>EffortJointInterface</hardwareInterface>
      <mechanicalReduction>1</mechanicalReduction>
</actuator>
  </transmission>
  <gazebo reference="l_ankle_roll">
<implicitSpringDamper>1</implicitSpringDamper>
  </gazebo>
  <joint name="r_hip_yaw" type="revolute">
<origin rpy="0 0 0" xyz="0.0 -0.072 -0.145"/>
<parent link="pelvis"/>
<child link="r_leg_hip_yaw"/>
<axis xyz="0 0 -1"/>
<limit effort="39.131" lower="-1.57079632679" upper="1.57079632679" velocity="2.5"/>
<dynamics damping="0.1" friction="0"/>
  </joint>
  <link name="r_leg_hip_yaw">
<inertial>
      <origin rpy="0 0 0" xyz="-0.0478 0.0 0.0"/>
<mass value="0.15"/>
<inertia ixx="3.75e-05" ixy="0.0" ixz="0.0" iyy="3.75e-05" iyz="0.0" izz="3.75e-05"/>
</inertial>
<visual>
<origin rpy=" 1.57079632679 0 -1.57079632679" xyz="0.0 0 0.063"/>
<geometry>
  <mesh filename="package://thor_mang_description/meshes/simple/hip_yaw_left.stl" scale="0.001 0.001 0.001"/>
</geometry>
<material name="blue">
  <color rgba="0.2 0.2 0.2 1"/>
</material>
</visual>
<collision>
<origin rpy="0 0 0" xyz="-0.02 0 0"/>
<geometry>
  <box size="0.16 0.08 0.08"/>
</geometry>
</collision>
  </link>
  <joint name="r_hip_roll" type="revolute">
<origin rpy="0 0 0" xyz="0 0 0"/>
    <parent link="r_leg_hip_yaw"/>
<child link="r_leg_hip_roll"/>
<axis xyz="-1 0 0"/>
<limit effort="21.142" lower="-1.57079632679" upper="1.57079632679" velocity="2.5"/>
<dynamics damping="0.1" friction="0"/>
  </joint>
  <link name="r_leg_hip_roll">
<inertial>
<origin rpy="0 0 0" xyz="-0.0216 0.0 0.0"/>
<mass value="1.02"/>
<inertia ixx="0.000255" ixy="0.0" ixz="0.0" iyy="0.000255" iyz="0.0" izz="0.000255"/>
</inertial>
<visual>
<origin rpy=" 1.57079632679 0 -1.57079632679" xyz="0.0 0 0"/>
<geometry>
  <mesh filename="package://thor_mang_description/meshes/simple/hip_roll_left.stl" scale="0.001 0.001 0.001"/>
</geometry>
<material name="blue">
  <color rgba="0.2 0.2 0.2 1"/>
</material>
</visual>
   <collision>
<origin rpy=" 3.14159265359 1.57079632679 0" xyz="-0.02 0 0"/>
<geometry>
  <box size="0.16 0.08 0.08"/>
</geometry>
    </collision>
  </link>
  <joint name="r_hip_pitch" type="revolute">
    <origin rpy="0 0 0" xyz="0 0 0"/>
<!--rpy="0.000329950722368627 -3.91151844547536E-19 1.16573417585641E-15"-->
<parent link="r_leg_hip_roll"/>
<child link="r_leg_thigh"/>
<axis xyz="0 -1 0"/>
<limit effort="39.131" lower="-1.57079632679" upper="1.57079632679" velocity="2.5"/>
<dynamics damping="0.1" friction="0"/>
  </joint>
  <link name="r_leg_thigh">
<inertial>
      <origin rpy="0 0 0" xyz="-0.0033 -0.0294 -0.172"/>
<mass value="3.12"/>
<inertia ixx="0.00702" ixy="0.0" ixz="0.0" iyy="0.00702" iyz="0.0" izz="0.00702"/>
</inertial>
<visual>
<origin rpy=" 1.57079632679 0 1.57079632679" xyz="0 0 -0.0"/>
<geometry>
  <mesh filename="package://thor_mang_description/meshes/simple/hip_pitch_left.stl" scale="-0.001 0.001  0.001"/>
</geometry>
<material name="blue">
  <color rgba="0.2 0.2 0.2 1"/>
</material>
</visual>
   <collision>
<origin rpy="0 0 0" xyz="0.01 -0.025 -0.15"/>
  <geometry>
  <box size="0.09 0.13 0.3"/>
</geometry>
</collision>
    <collision>
<origin rpy=" 0 0.785398163397 0" xyz="-0.03 -0.025 -0.3"/>
<geometry>
  <box size="0.06 0.14 0.06"/>
</geometry>
    </collision>
  </link>
  <joint name="r_knee" type="revolute">
<origin rpy="0 0 0" xyz="-0.03 0 -0.3"/>
<!--rpy="0.000329950722368627 -3.91151844547536E-19 1.16573417585641E-15"-->
<parent link="r_leg_thigh"/>
<child link="r_leg_shank"/>
<axis xyz="0 -1 0"/>
<limit effort="39.131" lower="-3.14159265359" upper="0.471238898038" velocity="2.5"/>
<dynamics damping="0.1" friction="0"/>
  </joint>
  <link name="r_leg_shank">
<inertial>
      <origin rpy="0 0 0" xyz="0.03 -0.0313 -0.17"/>
<mass value="2.24"/>
<inertia ixx="0.00504" ixy="0.0" ixz="0.0" iyy="0.00504" iyz="0.0" izz="0.00504"/>
</inertial>
<visual>
<origin rpy=" 1.57079632679 0 1.57079632679" xyz="0.03 0 0"/>
<geometry>
  <mesh filename="package://thor_mang_description/meshes/simple/leg_left.stl" scale="-0.001 0.001  0.001"/>
</geometry>
<material name="blue">
  <color rgba="0.2 0.2 0.2 1"/>
</material>
</visual>
   <collision>
<origin rpy="0 0 0" xyz="0.04 -0.025 -0.15"/>
  <geometry>
  <box size="0.09 0.13 0.3"/>
</geometry>
</collision>
  </link>
  <joint name="r_ankle_pitch" type="revolute">
<origin rpy="0 0 0" xyz="0.03 0 -0.3"/>
<!--rpy="0.000329950722368627 -3.91151844547536E-19 1.16573417585641E-15"-->
<parent link="r_leg_shank"/>
<child link="r_leg_ankle_roll"/>
<axis xyz="0 1.0 0"/>
<limit effort="39.131" lower="-1.82212373908" upper="1.82212373908" velocity="2.5"/>
<dynamics damping="0.1" friction="0"/>
  </joint>
  <link name="r_leg_ankle_roll">
<inertial>
<origin rpy="0 0 0" xyz="0.0 0.0 0.0"/>
<mass value="0.86"/>
<inertia ixx="0.0001376" ixy="0.0" ixz="0.0" iyy="0.0001376" iyz="0.0" izz="0.0001376"/>
</inertial>
<visual>
      <origin rpy=" 1.57079632679 0 -1.57079632679" xyz="0.0 0 0"/>
<geometry>
        <mesh filename="package://thor_mang_description/meshes/simple/ankle_roll_left.stl" scale="-0.001 0.001  0.001"/>
</geometry>
<material name="blue">
  <color rgba="0.2 0.2 0.2 1"/>
</material>
</visual>
   <collision>
<origin rpy="0 0 0" xyz="0 0 0"/>
<geometry>
        <box size="0.12 0.08 0.08"/>
</geometry>
</collision>
 </link>
  <joint name="r_ankle_roll" type="revolute">
<origin rpy="0 0 0" xyz="-0.0 0 0"/>
<!--rpy="0.000329950722368627 -3.91151844547536E-19 1.16573417585641E-15"-->
<parent link="r_leg_ankle_roll"/>
<child link="r_foot"/>
<axis xyz="1 0 0"/>
<limit effort="21.142" lower="-0.785398163397" upper="3.14159265359" velocity="2.5"/>
<dynamics damping="0.1" friction="0"/>
  </joint>
  <link name="r_foot">
<inertial>
     <origin rpy="0 0 0" xyz="0.0 0.0 -0.08"/>
<mass value="1.03"/>
<inertia ixx="0.0005047" ixy="0.0" ixz="0.0" iyy="0.0005047" iyz="0.0" izz="0.0005047"/>
</inertial>
<visual>
<origin rpy=" 1.57079632679 0 -1.57079632679" xyz="0.0 0 0"/>
<geometry>
  <mesh filename="package://thor_mang_description/meshes/simple/foot_left.stl" scale="0.001 0.001  0.001"/>
</geometry>
<material name="blue">
  <color rgba="0.2 0.2 0.2 1"/>
</material>
</visual>
<collision>
      <origin rpy="0 0 0" xyz="0.009 0 -0.098"/>
<geometry>
  <box size="0.24 0.144 0.04"/>
</geometry>
</collision>
<!--Additional collision geometry below foot to get more stable behavior in simulation-->
   <!--  
<collision>
<origin rpy="0 0 0" xyz="0.017 0.0 -0.118"/>
<geometry>
  <box size="0.265 0.15 0.01"/>
</geometry>
      <xacro:red/>
</collision>
-->
  </link>
  <gazebo reference="r_foot">
<!-- kp and kd for rubber -->
<kp>1000000.0</kp>
<kd>100.0</kd>
    <mu1>1.5</mu1>
<mu2>1.5</mu2>
<fdir1>1 0 0</fdir1>
<maxVel>1.0</maxVel>
    <minDepth>0.00</minDepth>
  </gazebo>
  <transmission name="r_hip_yaw_transmssion">
<type>transmission_interface/SimpleTransmission</type>
<joint name="r_hip_yaw">
<hardwareInterface>EffortJointInterface</hardwareInterface>
    </joint>
<actuator name="r_hip_yaw_motor">
<hardwareInterface>EffortJointInterface</hardwareInterface>
      <mechanicalReduction>1</mechanicalReduction>
</actuator>
  </transmission>
  <gazebo reference="r_hip_yaw">
<implicitSpringDamper>1</implicitSpringDamper>
  </gazebo>
  <transmission name="r_hip_roll_transmssion">
<type>transmission_interface/SimpleTransmission</type>
    <joint name="r_hip_roll">
<hardwareInterface>EffortJointInterface</hardwareInterface>
    </joint>
<actuator name="r_hip_roll_motor">
<hardwareInterface>EffortJointInterface</hardwareInterface>
      <mechanicalReduction>1</mechanicalReduction>
</actuator>
  </transmission>
  <gazebo reference="r_hip_roll">
<implicitSpringDamper>1</implicitSpringDamper>
  </gazebo>
  <transmission name="r_hip_pitch_transmssion">
<type>transmission_interface/SimpleTransmission</type>
    <joint name="r_hip_pitch">
<hardwareInterface>EffortJointInterface</hardwareInterface>
    </joint>
<actuator name="r_hip_pitch_motor">
<hardwareInterface>EffortJointInterface</hardwareInterface>
      <mechanicalReduction>1</mechanicalReduction>
</actuator>
  </transmission>
  <gazebo reference="r_hip_pitch">
<implicitSpringDamper>1</implicitSpringDamper>
  </gazebo>
  <transmission name="r_knee_transmssion">
<type>transmission_interface/SimpleTransmission</type>
    <joint name="r_knee">
<hardwareInterface>EffortJointInterface</hardwareInterface>
    </joint>
<actuator name="r_knee_motor">
<hardwareInterface>EffortJointInterface</hardwareInterface>
      <mechanicalReduction>1</mechanicalReduction>
</actuator>
  </transmission>
  <gazebo reference="r_knee">
<implicitSpringDamper>1</implicitSpringDamper>
  </gazebo>
  <transmission name="r_ankle_pitch_transmssion">
<type>transmission_interface/SimpleTransmission</type>
    <joint name="r_ankle_pitch">
<hardwareInterface>EffortJointInterface</hardwareInterface>
    </joint>
<actuator name="r_ankle_pitch_motor">
<hardwareInterface>EffortJointInterface</hardwareInterface>
      <mechanicalReduction>1</mechanicalReduction>
</actuator>
  </transmission>
  <gazebo reference="r_ankle_pitch">
<implicitSpringDamper>1</implicitSpringDamper>
  </gazebo>
  <transmission name="r_ankle_roll_transmssion">
<type>transmission_interface/SimpleTransmission</type>
    <joint name="r_ankle_roll">
<hardwareInterface>EffortJointInterface</hardwareInterface>
    </joint>
<actuator name="r_ankle_roll_motor">
<hardwareInterface>EffortJointInterface</hardwareInterface>
      <mechanicalReduction>1</mechanicalReduction>
</actuator>
  </transmission>
  <gazebo reference="r_ankle_roll">
<implicitSpringDamper>1</implicitSpringDamper>
  </gazebo>
  <joint name="l_shoulder_pitch" type="revolute">
<origin rpy="0 0.0 0" xyz="0.0 0.234 0.165"/>
<parent link="utorso"/>
    <child link="l_arm_shoulder_pitch"/>
<axis xyz="0 1 0"/>
<limit effort="39.131" lower="-3.14159265359" upper="3.14159265359" velocity="2.5"/>
<dynamics damping="0.1" friction="0"/>
  </joint>
  <link name="l_arm_shoulder_pitch">
<inertial>
<origin rpy="0 0 0" xyz="0.0 -0.001 -0.0"/>
<mass value="0.3"/>
<inertia ixx="2.7e-05" ixy="0.0" ixz="0.0" iyy="2.7e-05" iyz="0.0" izz="2.7e-05"/>
</inertial>
   <visual>
<origin rpy=" 3.14159265359 1.57079632679 0" xyz="0 -0.051 0"/>
<geometry>
  <mesh filename="package://thor_mang_description/meshes/simple/shoulder_pitch_left.stl" scale="0.001 0.001 0.001"/>
</geometry>
<material name="blue">
  <color rgba="0.2 0.2 0.2 1"/>
</material>
</visual>
   <collision>
<origin rpy="0 0 0" xyz="0 -0.01 0"/>
<geometry>
        <box size="0.16 0.085 0.06"/>
</geometry>
</collision>
  </link>
  <joint name="l_shoulder_roll" type="revolute">
<origin rpy="0.0 0 0" xyz="0.0 0.0 0"/>
<parent link="l_arm_shoulder_pitch"/>
    <child link="l_arm_shoulder_roll"/>
<axis xyz="-1 0 0"/>
<limit effort="39.131" lower="-3.14159265359" upper="3.14159265359" velocity="2.5"/>
<dynamics damping="0.1" friction="0"/>
  </joint>
  <link name="l_arm_shoulder_roll">
<inertial>
<origin rpy="0 0 0" xyz="0.0 0.0 -0.0"/>
<mass value="0.3"/>
<inertia ixx="2.7e-05" ixy="0.0" ixz="0.0" iyy="2.7e-05" iyz="0.0" izz="2.7e-05"/>
</inertial>
   <visual>
<origin rpy=" 1.57079632679 0 -1.57079632679" xyz="0.024 0 0"/>
<geometry>
  <mesh filename="package://thor_mang_description/meshes/simple/shoulder_roll_left.stl" scale="0.001 0.001 0.001"/>
</geometry>
<material name="blue">
  <color rgba="0.2 0.2 0.2 1"/>
</material>
</visual>
   <collision>
<origin rpy="0 0 0" xyz="0 0 0"/>
<geometry>
        <box size="0.16 0.06 0.06"/>
</geometry>
</collision>
 </link>
  <joint name="l_shoulder_yaw" type="revolute">
<origin rpy="0 0 0.0" xyz="0 0 0"/>
<!--rpy="0.000329950722368627 -3.91151844547536E-19 1.16573417585641E-15"-->
<parent link="l_arm_shoulder_roll"/>
<child link="l_arm_shoulder_yaw"/>
<axis xyz="0 0 -1"/>
<limit effort="39.131" lower="-3.14159265359" upper="3.14159265359" velocity="2.5"/>
   <dynamics damping="0.1" friction="0"/>
  </joint>
  <link name="l_arm_shoulder_yaw">
<inertial>
<origin rpy="0 0 0" xyz="0.0 0.0 -0.129"/>
<mass value="2.89"/>
<inertia ixx="0.0065025" ixy="0.0" ixz="0.0" iyy="0.0065025" iyz="0.0" izz="0.0065025"/>
</inertial>
<visual>
      <origin rpy=" 1.57079632679 0 -1.57079632679" xyz="0 0 -0.027"/>
  <geometry>
  <mesh filename="package://thor_mang_description/meshes/simple/shoulder_yaw_left.stl" scale="0.001 0.001 0.001"/>
</geometry>
<material name="blue">
  <color rgba="0.2 0.2 0.2 1"/>
</material>
</visual>
   <collision>
<origin rpy=" 0 0 0" xyz="0 0 -0.129"/>
<geometry>
        <box size="0.08 0.08 0.204"/>
</geometry>
</collision>
    <collision>
<origin rpy=" 0 0.785398163397 0" xyz="0.03 0 -0.246"/>
<geometry>
  <box size="0.06 0.13 0.06"/>
</geometry>
    </collision>
  </link>
  <joint name="l_elbow" type="revolute">
    <origin rpy="0 0.0 0" xyz="0.03 0 -0.246"/>
<!--rpy="0.000329950722368627 -3.91151844547536E-19 1.16573417585641E-15"-->
<parent link="l_arm_shoulder_yaw"/>
<child link="l_arm_elbow"/>
<axis xyz="0 1 0"/>
<limit effort="21.142" lower="-3.14159265359" upper="0.314159265359" velocity="2.5"/>
    <dynamics damping="0.1" friction="0"/>
  </joint>
  <link name="l_arm_elbow">
<inertial>
<origin rpy="0 0 0" xyz="0.0 0.0 -0.04"/>
<mass value="0.13"/>
<inertia ixx="3.25e-05" ixy="0.0" ixz="0.0" iyy="3.25e-05" iyz="0.0" izz="3.25e-05"/>
</inertial>
<visual>
  <origin rpy=" 1.57079632679 0 -1.57079632679" xyz="-0.03 0 0"/>
<geometry>
        <mesh filename="package://thor_mang_description/meshes/simple/elbow_left_mod.stl" scale="0.001 0.001 0.001"/>
</geometry>
<material name="blue">
  <color rgba="0.2 0.2 0.2 1"/>
</material>
</visual>
   <collision>
<origin rpy=" 0 0 0" xyz="-0.03 0 -0.02"/>
<geometry>
        <box size="0.06 0.13 0.08"/>
</geometry>
</collision>
 </link>
  <joint name="l_wrist_yaw1" type="revolute">
<origin rpy="0 0 1.57079632679" xyz="-0.030 0 -0.18600"/>
<!--rpy="0.000329950722368627 -3.91151844547536E-19 1.16573417585641E-15"-->
<parent link="l_arm_elbow"/>
<child link="l_arm_wrist_yaw"/>
<axis xyz="0 0 -1"/>
<limit effort="5.596" lower="-3.14159265359" upper="3.14159265359" velocity="1.4"/>
<dynamics damping="0.1" friction="0"/>
  </joint>
  <link name="l_arm_wrist_yaw">
<inertial>
<origin rpy="0 0 0" xyz="0.0 0.0 -0.0"/>
<mass value="0.81"/>
<inertia ixx="0.0002025" ixy="0.0" ixz="0.0" iyy="0.0002025" iyz="0.0" izz="0.0002025"/>
</inertial>
<visual>
      <origin rpy=" 1.57079632679 0 -1.57079632679" xyz="0 0 0"/>
<geometry>
        <mesh filename="package://thor_mang_description/meshes/simple/wrist_yaw_left_mod.stl" scale="0.001 0.001 0.001"/>
</geometry>
<material name="blue">
  <color rgba="0.2 0.2 0.2 1"/>
</material>
</visual>
   <collision>
<origin rpy="0 0 0" xyz="0 0 0"/>
<geometry>
        <box size="0.1 0.06 0.06"/>
</geometry>
</collision>
  <collision>
<origin rpy=" 0 0 0" xyz="0 0 0.07"/>
<geometry>
        <box size="0.06 0.06 0.10"/>
</geometry>
</collision>
 </link>
  <joint name="l_wrist_roll" type="revolute">
<origin rpy="0.0 0 0" xyz="0 0 0"/>
<!--rpy="0.000329950722368627 -3.91151844547536E-19 1.16573417585641E-15"-->
<parent link="l_arm_wrist_yaw"/>
<child link="l_arm_wrist_roll"/>
<axis xyz="1 0 0"/>
<limit effort="5.596" lower="-1.88495559215" upper="1.88495559215" velocity="1.4"/>
<dynamics damping="0.1" friction="0"/>
  </joint>
  <link name="l_arm_wrist_roll">
<inertial>
<origin rpy="0 0 0" xyz="0.0 0.0 -0.03"/>
<mass value="0.27"/>
<inertia ixx="2.43e-05" ixy="0.0" ixz="0.0" iyy="2.43e-05" iyz="0.0" izz="2.43e-05"/>
</inertial>
<visual>
  <origin rpy=" 1.57079632679 0 -1.57079632679" xyz="0 0 0"/>
<geometry>
        <mesh filename="package://thor_mang_description/meshes/simple/wrist_roll_left_mod.stl" scale="-0.001 0.001 0.001"/>
</geometry>
<material name="blue">
  <color rgba="0.2 0.2 0.2 1"/>
</material>
</visual>
   <collision>
<origin rpy="0 0 0" xyz="0 0 0"/>
<geometry>
        <box size="0.1 0.06 0.06"/>
</geometry>
</collision>
  <collision>
<origin rpy=" 0 0 0" xyz="0 0 -0.08"/>
<geometry>
        <box size="0.06 0.06 0.10"/>
</geometry>
</collision>
 </link>
  <joint name="l_wrist_yaw2" type="revolute">
<origin rpy="0.0 0 0" xyz="0 0 0"/>
<!--rpy="0.000329950722368627 -3.91151844547536E-19 1.16573417585641E-15"-->
<parent link="l_arm_wrist_roll"/>
<child link="l_arm_wrist_yaw2"/>
<axis xyz="0 0 -1"/>
<limit effort="5.596" lower="-4.08407044967" upper="4.08407044967" velocity="1.4"/>
  <dynamics damping="0.1" friction="0"/>
  </joint>
  <link name="l_arm_wrist_yaw2">
<inertial>
<origin rpy="0 0 0" xyz="0.0 0.0 -0.0"/>
<mass value="0.81"/>
<inertia ixx="0.0002025" ixy="0.0" ixz="0.0" iyy="0.0002025" iyz="0.0" izz="0.0002025"/>
</inertial>
<visual>
      <origin rpy=" 0 0 0" xyz="0 0 -0.135"/>
<geometry>
  <box size="0.035 .035 .01"/>
  <!--<mesh
    filename="package://thor_mang_description/meshes/simple/wrist_yaw_left.stl" scale="0.001 0.001 0.001"/>-->
</geometry>
<material name="blue">
  <color rgba="0.2 0.2 0.2 1"/>
</material>
</visual>
   <collision>
<origin rpy=" 0 0 0" xyz="0 0 -0.135"/>
<geometry>
        <box size="0.035 .035 .01"/>
  <!--<mesh
    filename="package://thor_mang_description/meshes/simple/wrist_yaw_left.stl" scale="0.001 0.001 0.001"/>-->
</geometry>
</collision>
  </link>
  <joint name="l_hand_joint" type="fixed">
<origin rpy="0 0 0" xyz="0 0 -0.135"/>
    <parent link="l_arm_wrist_yaw2"/>
<child link="l_hand_force_torque"/>
  </joint>
  <link name="l_hand_force_torque">
  </link>
  <transmission name="l_shoulder_pitch_transmssion">
<type>transmission_interface/SimpleTransmission</type>
<joint name="l_shoulder_pitch">
<hardwareInterface>EffortJointInterface</hardwareInterface>
    </joint>
<actuator name="l_shoulder_pitch_motor">
<hardwareInterface>EffortJointInterface</hardwareInterface>
      <mechanicalReduction>1</mechanicalReduction>
</actuator>
  </transmission>
  <gazebo reference="l_shoulder_pitch">
<implicitSpringDamper>1</implicitSpringDamper>
  </gazebo>
  <transmission name="l_shoulder_roll_transmssion">
<type>transmission_interface/SimpleTransmission</type>
    <joint name="l_shoulder_roll">
<hardwareInterface>EffortJointInterface</hardwareInterface>
    </joint>
<actuator name="l_shoulder_roll_motor">
<hardwareInterface>EffortJointInterface</hardwareInterface>
      <mechanicalReduction>1</mechanicalReduction>
</actuator>
  </transmission>
  <gazebo reference="l_shoulder_roll">
<implicitSpringDamper>1</implicitSpringDamper>
  </gazebo>
  <transmission name="l_shoulder_yaw_transmssion">
<type>transmission_interface/SimpleTransmission</type>
    <joint name="l_shoulder_yaw">
<hardwareInterface>EffortJointInterface</hardwareInterface>
    </joint>
<actuator name="l_shoulder_yaw_motor">
<hardwareInterface>EffortJointInterface</hardwareInterface>
      <mechanicalReduction>1</mechanicalReduction>
</actuator>
  </transmission>
  <gazebo reference="l_shoulder_yaw">
<implicitSpringDamper>1</implicitSpringDamper>
  </gazebo>
  <transmission name="l_elbow_transmssion">
<type>transmission_interface/SimpleTransmission</type>
    <joint name="l_elbow">
<hardwareInterface>EffortJointInterface</hardwareInterface>
    </joint>
<actuator name="l_elbow_motor">
<hardwareInterface>EffortJointInterface</hardwareInterface>
      <mechanicalReduction>1</mechanicalReduction>
</actuator>
  </transmission>
  <gazebo reference="l_elbow">
<implicitSpringDamper>1</implicitSpringDamper>
  </gazebo>
  <transmission name="l_wrist_yaw1_transmssion">
<type>transmission_interface/SimpleTransmission</type>
    <joint name="l_wrist_yaw1">
<hardwareInterface>EffortJointInterface</hardwareInterface>
    </joint>
<actuator name="l_wrist_yaw1_motor">
<hardwareInterface>EffortJointInterface</hardwareInterface>
      <mechanicalReduction>1</mechanicalReduction>
</actuator>
  </transmission>
  <gazebo reference="l_wrist_yaw1">
<implicitSpringDamper>1</implicitSpringDamper>
  </gazebo>
  <transmission name="l_wrist_roll_transmssion">
<type>transmission_interface/SimpleTransmission</type>
    <joint name="l_wrist_roll">
<hardwareInterface>EffortJointInterface</hardwareInterface>
    </joint>
<actuator name="l_wrist_roll_motor">
<hardwareInterface>EffortJointInterface</hardwareInterface>
      <mechanicalReduction>1</mechanicalReduction>
</actuator>
  </transmission>
  <gazebo reference="l_wrist_roll">
<implicitSpringDamper>1</implicitSpringDamper>
  </gazebo>
  <transmission name="l_wrist_yaw2_transmssion">
<type>transmission_interface/SimpleTransmission</type>
    <joint name="l_wrist_yaw2">
<hardwareInterface>EffortJointInterface</hardwareInterface>
    </joint>
<actuator name="l_wrist_yaw2_motor">
<hardwareInterface>EffortJointInterface</hardwareInterface>
      <mechanicalReduction>1</mechanicalReduction>
</actuator>
  </transmission>
  <gazebo reference="l_wrist_yaw2">
<implicitSpringDamper>1</implicitSpringDamper>
  </gazebo>
  <joint name="r_shoulder_pitch" type="revolute">
<origin rpy="0 0.0 0" xyz="0.0 -0.234 0.165"/>
<parent link="utorso"/>
  <child link="r_arm_shoulder_pitch"/>
<axis xyz="0 -1 0"/>
<limit effort="39.131" lower="-3.14159265359" upper="3.14159265359" velocity="2.5"/>
<dynamics damping="0.1" friction="0"/>
  </joint>
  <link name="r_arm_shoulder_pitch">
<inertial>
<origin rpy="0 0 0" xyz="0.0 0.001 -0.0"/>
<mass value="0.3"/>
<inertia ixx="2.7e-05" ixy="0.0" ixz="0.0" iyy="2.7e-05" iyz="0.0" izz="2.7e-05"/>
</inertial>
   <visual>
<origin rpy=" 3.14159265359 1.57079632679 0" xyz="0 0.051 0"/>
<geometry>
  <mesh filename="package://thor_mang_description/meshes/simple/shoulder_pitch_left.stl" scale="0.001 -0.001 0.001"/>
</geometry>
<material name="blue">
  <color rgba="0.2 0.2 0.2 1"/>
</material>
</visual>
   <collision>
<origin rpy="0 0 0" xyz="0 0.01 0"/>
<geometry>
        <box size="0.16 0.085 0.06"/>
</geometry>
</collision>
  </link>
  <joint name="r_shoulder_roll" type="revolute">
<origin rpy="0.0 0 0" xyz="0.0 0.0 0"/>
<parent link="r_arm_shoulder_pitch"/>
    <child link="r_arm_shoulder_roll"/>
<axis xyz="-1 0 0"/>
<limit effort="39.131" lower="-3.14159265359" upper="3.14159265359" velocity="2.5"/>
<dynamics damping="0.1" friction="0"/>
  </joint>
  <link name="r_arm_shoulder_roll">
<inertial>
<origin rpy="0 0 0" xyz="0.0 0.0 -0.0"/>
<mass value="0.3"/>
<inertia ixx="2.7e-05" ixy="0.0" ixz="0.0" iyy="2.7e-05" iyz="0.0" izz="2.7e-05"/>
</inertial>
   <visual>
<origin rpy=" 1.57079632679 0 -1.57079632679" xyz="0.024 0 0"/>
<geometry>
  <mesh filename="package://thor_mang_description/meshes/simple/shoulder_roll_left.stl" scale="0.001 0.001 0.001"/>
</geometry>
<material name="blue">
  <color rgba="0.2 0.2 0.2 1"/>
</material>
</visual>
   <collision>
<origin rpy="0 0 0" xyz="0 0 0"/>
<geometry>
        <box size="0.16 0.06 0.06"/>
</geometry>
</collision>
 </link>
  <joint name="r_shoulder_yaw" type="revolute">
<origin rpy="0 0 0.0" xyz="0 0 0"/>
<!--rpy="0.000329950722368627 -3.91151844547536E-19 1.16573417585641E-15"-->
<parent link="r_arm_shoulder_roll"/>
<child link="r_arm_shoulder_yaw"/>
<axis xyz="0 0 -1"/>
<limit effort="39.131" lower="-3.14159265359" upper="3.14159265359" velocity="2.5"/>
   <dynamics damping="0.1" friction="0"/>
  </joint>
  <link name="r_arm_shoulder_yaw">
<inertial>
<origin rpy="0 0 0" xyz="0.0 0.0 -0.129"/>
<mass value="2.89"/>
<inertia ixx="0.0065025" ixy="0.0" ixz="0.0" iyy="0.0065025" iyz="0.0" izz="0.0065025"/>
</inertial>
<visual>
      <origin rpy=" 1.57079632679 0 -1.57079632679" xyz="0 0 -0.027"/>
  <geometry>
  <mesh filename="package://thor_mang_description/meshes/simple/shoulder_yaw_left.stl" scale="0.001 0.001 0.001"/>
</geometry>
<material name="blue">
  <color rgba="0.2 0.2 0.2 1"/>
</material>
</visual>
   <collision>
<origin rpy=" 0 0 0" xyz="0 0 -0.129"/>
<geometry>
        <box size="0.08 0.08 0.204"/>
</geometry>
</collision>
    <collision>
<origin rpy=" 0 0.785398163397 0" xyz="0.03 0 -0.246"/>
<geometry>
  <box size="0.06 0.13 0.06"/>
</geometry>
    </collision>
  </link>
  <joint name="r_elbow" type="revolute">
    <origin rpy="0 0.0 0" xyz="0.03 0 -0.246"/>
<!--rpy="0.000329950722368627 -3.91151844547536E-19 1.16573417585641E-15"-->
<parent link="r_arm_shoulder_yaw"/>
<child link="r_arm_elbow"/>
<axis xyz="0 -1 0"/>
<limit effort="21.142" lower="-0.314159265359" upper="3.14159265359" velocity="2.5"/>
    <dynamics damping="0.1" friction="0"/>
  </joint>
  <link name="r_arm_elbow">
<inertial>
<origin rpy="0 0 0" xyz="0.0 0.0 -0.04"/>
<mass value="0.13"/>
<inertia ixx="3.25e-05" ixy="0.0" ixz="0.0" iyy="3.25e-05" iyz="0.0" izz="3.25e-05"/>
</inertial>
<visual>
  <origin rpy=" 1.57079632679 0 -1.57079632679" xyz="-0.03 0 0"/>
<geometry>
        <mesh filename="package://thor_mang_description/meshes/simple/elbow_left_mod.stl" scale="0.001 0.001 0.001"/>
</geometry>
<material name="blue">
  <color rgba="0.2 0.2 0.2 1"/>
</material>
</visual>
   <collision>
<origin rpy=" 0 0 0" xyz="-0.03 0 -0.02"/>
<geometry>
        <box size="0.06 0.13 0.08"/>
</geometry>
</collision>
 </link>
  <joint name="r_wrist_yaw1" type="revolute">
<origin rpy="0 0 -1.57079632679" xyz="-0.030 0 -0.18600"/>
<!--rpy="0.000329950722368627 -3.91151844547536E-19 1.16573417585641E-15"-->
<parent link="r_arm_elbow"/>
<child link="r_arm_wrist_yaw"/>
<axis xyz="0 0 -1"/>
<limit effort="5.596" lower="-3.14159265359" upper="3.14159265359" velocity="1.4"/>
<dynamics damping="0.1" friction="0"/>
  </joint>
  <link name="r_arm_wrist_yaw">
<inertial>
<origin rpy="0 0 0" xyz="0.0 0.0 -0.0"/>
<mass value="0.81"/>
<inertia ixx="0.0002025" ixy="0.0" ixz="0.0" iyy="0.0002025" iyz="0.0" izz="0.0002025"/>
</inertial>
<visual>
      <origin rpy=" 1.57079632679 0 -1.57079632679" xyz="0 0 0"/>
<geometry>
        <mesh filename="package://thor_mang_description/meshes/simple/wrist_yaw_left_mod.stl" scale="0.001 0.001 0.001"/>
</geometry>
<material name="blue">
  <color rgba="0.2 0.2 0.2 1"/>
</material>
</visual>
   <collision>
<origin rpy="0 0 0" xyz="0 0 0"/>
<geometry>
        <box size="0.1 0.06 0.06"/>
</geometry>
</collision>
  <collision>
<origin rpy=" 0 0 0" xyz="0 0 0.07"/>
<geometry>
        <box size="0.06 0.06 0.10"/>
</geometry>
</collision>
 </link>
  <joint name="r_wrist_roll" type="revolute">
<origin rpy="0.0 0 0" xyz="0 0 0"/>
<!--rpy="0.000329950722368627 -3.91151844547536E-19 1.16573417585641E-15"-->
<parent link="r_arm_wrist_yaw"/>
<child link="r_arm_wrist_roll"/>
<axis xyz="1 0 0"/>
<limit effort="5.596" lower="-1.88495559215" upper="1.88495559215" velocity="1.4"/>
<dynamics damping="0.1" friction="0"/>
  </joint>
  <link name="r_arm_wrist_roll">
<inertial>
<origin rpy="0 0 0" xyz="0.0 0.0 -0.03"/>
<mass value="0.27"/>
<inertia ixx="2.43e-05" ixy="0.0" ixz="0.0" iyy="2.43e-05" iyz="0.0" izz="2.43e-05"/>
</inertial>
<visual>
  <origin rpy=" 1.57079632679 0 -1.57079632679" xyz="0 0 0"/>
<geometry>
        <mesh filename="package://thor_mang_description/meshes/simple/wrist_roll_left_mod.stl" scale="0.001 0.001 0.001"/>
</geometry>
<material name="blue">
  <color rgba="0.2 0.2 0.2 1"/>
</material>
</visual>
   <collision>
<origin rpy="0 0 0" xyz="0 0 0"/>
<geometry>
        <box size="0.1 0.06 0.06"/>
</geometry>
</collision>
  <collision>
<origin rpy=" 0 0 0" xyz="0 0 -0.08"/>
<geometry>
        <box size="0.06 0.06 0.10"/>
</geometry>
</collision>
 </link>
  <joint name="r_wrist_yaw2" type="revolute">
<origin rpy="0.0 0 0" xyz="0 0 0"/>
<!--rpy="0.000329950722368627 -3.91151844547536E-19 1.16573417585641E-15"-->
<parent link="r_arm_wrist_roll"/>
<child link="r_arm_wrist_yaw2"/>
<axis xyz="0 0 -1"/>
<limit effort="5.596" lower="-4.08407044967" upper="4.08407044967" velocity="1.4"/>
  <dynamics damping="0.1" friction="0"/>
  </joint>
  <link name="r_arm_wrist_yaw2">
<inertial>
<origin rpy="0 0 0" xyz="0.0 0.0 -0.0"/>
<mass value="0.81"/>
<inertia ixx="0.0002025" ixy="0.0" ixz="0.0" iyy="0.0002025" iyz="0.0" izz="0.0002025"/>
</inertial>
<visual>
      <origin rpy=" 0 0 0" xyz="0 0 -0.135"/>
<geometry>
  <box size="0.035 .035 .01"/>
  <!--<mesh
    filename="package://thor_mang_description/meshes/simple/wrist_yaw_left.stl" scale="0.001 0.001 0.001"/>-->
</geometry>
<material name="blue">
  <color rgba="0.2 0.2 0.2 1"/>
</material>
</visual>
   <collision>
<origin rpy=" 0 0 0" xyz="0 0 -0.135"/>
<geometry>
        <box size="0.035 .035 .01"/>
  <!--<mesh
    filename="package://thor_mang_description/meshes/simple/wrist_yaw_left.stl" scale="0.001 0.001 0.001"/>-->
</geometry>
</collision>
  </link>
  <joint name="r_hand_joint" type="fixed">
<origin rpy="0 0 0" xyz="0 0 -0.135"/>
    <parent link="r_arm_wrist_yaw2"/>
<child link="right_palm"/>
  </joint>
  <link name="right_palm">
  </link>
  <transmission name="r_shoulder_pitch_transmssion">
<type>transmission_interface/SimpleTransmission</type>
<joint name="r_shoulder_pitch">
<hardwareInterface>EffortJointInterface</hardwareInterface>
    </joint>
<actuator name="r_shoulder_pitch_motor">
<hardwareInterface>EffortJointInterface</hardwareInterface>
      <mechanicalReduction>1</mechanicalReduction>
</actuator>
  </transmission>
  <gazebo reference="r_shoulder_pitch">
<implicitSpringDamper>1</implicitSpringDamper>
  </gazebo>
  <transmission name="r_shoulder_roll_transmssion">
<type>transmission_interface/SimpleTransmission</type>
    <joint name="r_shoulder_roll">
<hardwareInterface>EffortJointInterface</hardwareInterface>
    </joint>
<actuator name="r_shoulder_roll_motor">
<hardwareInterface>EffortJointInterface</hardwareInterface>
      <mechanicalReduction>1</mechanicalReduction>
</actuator>
  </transmission>
  <gazebo reference="r_shoulder_roll">
<implicitSpringDamper>1</implicitSpringDamper>
  </gazebo>
  <transmission name="r_shoulder_yaw_transmssion">
<type>transmission_interface/SimpleTransmission</type>
    <joint name="r_shoulder_yaw">
<hardwareInterface>EffortJointInterface</hardwareInterface>
    </joint>
<actuator name="r_shoulder_yaw_motor">
<hardwareInterface>EffortJointInterface</hardwareInterface>
      <mechanicalReduction>1</mechanicalReduction>
</actuator>
  </transmission>
  <gazebo reference="r_shoulder_yaw">
<implicitSpringDamper>1</implicitSpringDamper>
  </gazebo>
  <transmission name="r_elbow_transmssion">
<type>transmission_interface/SimpleTransmission</type>
    <joint name="r_elbow">
<hardwareInterface>EffortJointInterface</hardwareInterface>
    </joint>
<actuator name="r_elbow_motor">
<hardwareInterface>EffortJointInterface</hardwareInterface>
      <mechanicalReduction>1</mechanicalReduction>
</actuator>
  </transmission>
  <gazebo reference="r_elbow">
<implicitSpringDamper>1</implicitSpringDamper>
  </gazebo>
  <transmission name="r_wrist_yaw1_transmssion">
<type>transmission_interface/SimpleTransmission</type>
    <joint name="r_wrist_yaw1">
<hardwareInterface>EffortJointInterface</hardwareInterface>
    </joint>
<actuator name="r_wrist_yaw1_motor">
<hardwareInterface>EffortJointInterface</hardwareInterface>
      <mechanicalReduction>1</mechanicalReduction>
</actuator>
  </transmission>
  <gazebo reference="r_wrist_yaw1">
<implicitSpringDamper>1</implicitSpringDamper>
  </gazebo>
  <transmission name="r_wrist_roll_transmssion">
<type>transmission_interface/SimpleTransmission</type>
    <joint name="r_wrist_roll">
<hardwareInterface>EffortJointInterface</hardwareInterface>
    </joint>
<actuator name="r_wrist_roll_motor">
<hardwareInterface>EffortJointInterface</hardwareInterface>
      <mechanicalReduction>1</mechanicalReduction>
</actuator>
  </transmission>
  <gazebo reference="r_wrist_roll">
<implicitSpringDamper>1</implicitSpringDamper>
  </gazebo>
  <transmission name="r_wrist_yaw2_transmssion">
<type>transmission_interface/SimpleTransmission</type>
    <joint name="r_wrist_yaw2">
<hardwareInterface>EffortJointInterface</hardwareInterface>
    </joint>
<actuator name="r_wrist_yaw2_motor">
<hardwareInterface>EffortJointInterface</hardwareInterface>
      <mechanicalReduction>1</mechanicalReduction>
</actuator>
  </transmission>
  <gazebo reference="r_wrist_yaw2">
<implicitSpringDamper>1</implicitSpringDamper>
  </gazebo>
  <joint name="head_pan" type="revolute">
<origin rpy="0 0.0 0" xyz="0.0 0.0 0.320"/>
<parent link="utorso"/>
<child link="neck_link"/>
<axis xyz="0 0 1"/>
<limit effort="5.596" lower="-3.14159265359" upper="3.14159265359" velocity="1.4"/>
<dynamics damping="0.1" friction="0"/>
  </joint>
  <link name="neck_link">
<inertial>
<origin rpy="0 0 0" xyz="0.0 0.0 0.0"/>
<mass value="0.1"/>
<inertia ixx="9e-06" ixy="0.0" ixz="0.0" iyy="9e-06" iyz="0.0" izz="9e-06"/>
</inertial>
    <visual>
<origin rpy=" 1.57079632679 0 -1.57079632679" xyz="0 0 -0.111"/>
<geometry>
  <mesh filename="package://thor_mang_description/meshes/simple/neck.stl" scale="0.001 0.001 0.001"/>
</geometry>
<material name="blue">
  <color rgba="0.2 0.2 0.2 1"/>
</material>
</visual>
   <collision>
<origin rpy="0 0 0" xyz="0 0 -0.05"/>
<geometry>
        <box size="0.045 0.045 0.15"/>
</geometry>
</collision>
  </link>
  <joint name="head_tilt" type="revolute">
<origin rpy="0 0.0 0" xyz="0 0 0"/>
<parent link="neck_link"/>
<child link="head_link"/>
<axis xyz="0 1 0"/>
<limit effort="5.596" lower="-1.57079632679" upper="1.57079632679" velocity="1.4"/>
<dynamics damping="0.1" friction="0"/>
  </joint>
  <transmission name="head_pan_transmssion">
<type>transmission_interface/SimpleTransmission</type>
    <joint name="head_pan">
<hardwareInterface>EffortJointInterface</hardwareInterface>
    </joint>
<actuator name="head_pan_motor">
<hardwareInterface>EffortJointInterface</hardwareInterface>
      <mechanicalReduction>1</mechanicalReduction>
</actuator>
  </transmission>
  <gazebo reference="head_pan">
<implicitSpringDamper>1</implicitSpringDamper>
  </gazebo>
  <transmission name="head_tilt_transmssion">
<type>transmission_interface/SimpleTransmission</type>
    <joint name="head_tilt">
<hardwareInterface>EffortJointInterface</hardwareInterface>
    </joint>
<actuator name="head_tilt_motor">
<hardwareInterface>EffortJointInterface</hardwareInterface>
      <mechanicalReduction>1</mechanicalReduction>
</actuator>
  </transmission>
  <gazebo reference="head_tilt">
<implicitSpringDamper>1</implicitSpringDamper>
  </gazebo>
  <link name="head_link">
<inertial>
<origin rpy="0 0 0" xyz="0.0 0.0 -0.0"/>
<mass value="0.1"/>
<inertia ixx="9e-06" ixy="0.0" ixz="0.0" iyy="9e-06" iyz="0.0" izz="9e-06"/>
</inertial>
    <visual>
<origin rpy=" 1.57079632679 0 1.57079632679" xyz="0 0 0"/>
<geometry>
  <mesh filename="package://thor_mang_description/meshes/simple/head.stl" scale="0.001 0.001 0.001"/>
</geometry>
<material name="blue">
  <color rgba="0.2 0.2 0.2 1"/>
</material>
</visual>
   <!--   <collision>
<origin xyz="0.01 0 0.075" rpy="0 0 0" />
    <geometry>
  <box size="0.16 0.1 0.1" />
</geometry>
</collision>-->
    <collision>
<origin rpy="0 0 0" xyz="-0.05 0 0.075"/>
<geometry>
        <box size="0.10 0.1 0.1"/>
</geometry>
</collision>
  </link>
  <joint name="head_link_hokuyo_laser_joint" type="fixed">
<origin rpy="0 0 0" xyz="0.043 0.0 0.11"/>
<parent link="head_link"/>
<child link="head_link_hokuyo_laser_frame"/>
  </joint>
  <link name="head_link_hokuyo_laser_frame">
<inertial>
<mass value="0.270"/>
<origin rpy="0 0 0" xyz="0 0 0"/>
<inertia ixx="2.632e-4" ixy="0" ixz="0" iyy="2.632e-4" iyz="0" izz="1.62e-4"/>
</inertial>
<visual>
<origin rpy="0 0 0" xyz="0 0 0"/>
<geometry>
  <box size="0.058 0.058 0.087"/>
<!--  <mesh filename="package://thor_mang_description/meshes/hokuyo_utm30lx/hokuyo_utm_30lx.dae"/>-->
</geometry>
</visual>
<collision>
<origin rpy="0 0 0" xyz="0 0 -0.0115"/>
<geometry>
  <box size="0.058 0.058 0.087"/>
  <!--<mesh filename="package://thor_mang_description/meshes/hokuyo_utm30lx/hokuyo_utm_30lx.stl"/>-->
</geometry>
</collision>
  </link>
  <gazebo reference="head_link_hokuyo_laser_frame">
<sensor name="head_link_hokuyo_laser" type="ray">
<always_on>true</always_on>
      <update_rate>40</update_rate>
<pose>0 0 0 0 0 0</pose>
<visualize>false</visualize>
      <ray>
  <scan>
    <horizontal>
      <samples>1040</samples>
            <resolution>1</resolution>
      <min_angle>2.26892802759</min_angle>
            <max_angle>-2.26892802759</max_angle>
    </horizontal>
      </scan>
  <range>
    <min>0.08</min>
    <max>30.0</max>
          <resolution>0.01</resolution>
  </range>
</ray>
  <plugin filename="libgazebo_ros_laser.so" name="gazebo_ros_head_link_hokuyo_laser_controller">
  <gaussianNoise>0.005</gaussianNoise>
  <alwaysOn>true</alwaysOn>
        <updateRate>40</updateRate>
  <topicName>/head_lidar/scan</topicName>
        <frameName>head_link_hokuyo_laser_frame</frameName>
</plugin>
    </sensor>
  </gazebo>
  <joint name="head_cam_joint" type="fixed">
    <origin rpy="0 0 0" xyz="0.08 0.0 0.035"/>
<parent link="head_link"/>
<child link="head_cam_link"/>
  </joint>
  <link name="head_cam_link">
<inertial>
<mass value="0.001"/>
<origin rpy="0 0 0" xyz="0 0 0"/>
<inertia ixx="0.0001" ixy="0" ixz="0" iyy="0.0001" iyz="0" izz="0.0001"/>
</inertial>
<visual>
<origin rpy="0 0 0" xyz="0 0 0"/>
<geometry>
  <box size="0.01 0.01 0.01"/>
    </geometry>
<material name="Blue">
  <color rgba="0.0 0.0 0.8 1"/>
</material>
</visual>
<collision>
<origin rpy="0 0 0" xyz="0 0 0"/>
<geometry>
  <box size="0.01 0.01 0.01"/>
</geometry>
</collision>
  </link>
  <joint name="head_cam_optical_joint" type="fixed">
<origin rpy="-1.57079632679 0.0 -1.57079632679" xyz="0 0 0"/>
<parent link="head_cam_link"/>
<child link="head_cam_optical_frame"/>
  </joint>
  <link name="head_cam_optical_frame"/>
  <gazebo reference="head_cam_link">
<sensor name="head_cam_camera_sensor" type="camera">
      <update_rate>10</update_rate>
<camera>
  <horizontal_fov>1.57079632679</horizontal_fov>
        <image>
    <format>R8G8B8</format>
    <width>640</width>
          <height>480</height>
  </image>
  <clip>
    <near>0.01</near>
          <far>100</far>
  </clip>
</camera>
<plugin filename="libgazebo_ros_camera.so" name="head_cam_camera_controller">
  <cameraName>head_cam</cameraName>
        <alwaysOn>true</alwaysOn>
  <updateRate>10</updateRate>
  <imageTopicName>image_raw</imageTopicName>
  <cameraInfoTopicName>camera_info</cameraInfoTopicName>
        <frameName>head_cam_optical_frame</frameName>
</plugin>
</sensor>
  </gazebo>
  <joint name="waist_lidar" type="revolute">
<origin rpy="0 0.0 0" xyz="0.0 0.0 0.0878"/>
<parent link="utorso"/>
<child link="waist_lidar_mount_link"/>
<axis xyz="0 0 -1"/>
<limit effort="5.596" lower="-1.57079632679" upper="1.57079632679" velocity="1.4"/>
<dynamics damping="0.1" friction="0"/>
  </joint>
  <link name="waist_lidar_mount_link">
<inertial>
<origin rpy="0 0 0" xyz="0.0 0.0 0.0"/>
<mass value="0.1"/>
<inertia ixx="9e-06" ixy="0.0" ixz="0.0" iyy="9e-06" iyz="0.0" izz="9e-06"/>
</inertial>
<!--    <visual>
<origin
        xyz="0 0 -0.111"
  rpy=" ${M_PI*0.5} 0 ${-M_PI*0.5}" />
    <geometry>
  <mesh
    filename="package://thor_mang_description/meshes/simple/neck.stl" scale="0.001 0.001 0.001"/>
</geometry>
<xacro:black/>
</visual>
    <collision>
<origin
  xyz="0 0 -0.111"
  rpy=" ${M_PI*0.5} 0 ${-M_PI*0.5}" />
<geometry>
  <mesh
    filename="package://thor_mang_description/meshes/simple/neck.stl" scale="0.001 0.001 0.001"/>
</geometry>
</collision>-->
  </link>
  <joint name="waist_hokuyo_laser_joint" type="fixed">
<origin rpy="-1.57079632679 0 0" xyz="0.023 0.0 0.0"/>
<parent link="waist_lidar_mount_link"/>
<child link="waist_hokuyo_laser_frame"/>
  </joint>
  <link name="waist_hokuyo_laser_frame">
<inertial>
<mass value="0.270"/>
      <origin rpy="0 0 0" xyz="0 0 0"/>
<inertia ixx="2.632e-4" ixy="0" ixz="0" iyy="2.632e-4" iyz="0" izz="1.62e-4"/>
</inertial>
  <visual>
<origin rpy="0 0 0" xyz="0 0 -0.0115"/>
<geometry>
  <box size="0.058 0.058 0.087"/>
<!--        <mesh filename="package://thor_mang_description/meshes/hokuyo_utm30lx/hokuyo_utm_30lx.dae"/>-->
</geometry>
</visual>
<collision>
<origin rpy="0 0 0" xyz="0 0 -0.0115"/>
<geometry>
  <box size="0.058 0.058 0.087"/>
  <!--<mesh filename="package://thor_mang_description/meshes/hokuyo_utm30lx/hokuyo_utm_30lx.stl"/>-->
</geometry>
</collision>
  </link>
  <gazebo reference="waist_hokuyo_laser_frame">
<sensor name="waist_hokuyo_laser" type="ray">
<always_on>true</always_on>
      <update_rate>40</update_rate>
<pose>0 0 0 0 0 0</pose>
<visualize>false</visualize>
      <ray>
  <scan>
    <horizontal>
      <samples>1040</samples>
            <resolution>1</resolution>
      <min_angle>2.26892802759</min_angle>
            <max_angle>-2.26892802759</max_angle>
    </horizontal>
      </scan>
  <range>
    <min>0.08</min>
    <max>30.0</max>
          <resolution>0.01</resolution>
  </range>
</ray>
  <plugin filename="libgazebo_ros_laser.so" name="gazebo_ros_waist_hokuyo_laser_controller">
  <gaussianNoise>0.005</gaussianNoise>
  <alwaysOn>true</alwaysOn>
        <updateRate>40</updateRate>
  <topicName>/chest_lidar/scan</topicName>
        <frameName>waist_hokuyo_laser_frame</frameName>
</plugin>
</sensor>
  </gazebo>
  <transmission name="waist_lidar_transmssion">
<type>transmission_interface/SimpleTransmission</type>
    <joint name="waist_lidar">
<hardwareInterface>EffortJointInterface</hardwareInterface>
    </joint>
<actuator name="waist_lidar_motor">
<hardwareInterface>EffortJointInterface</hardwareInterface>
      <mechanicalReduction>1</mechanicalReduction>
</actuator>
  </transmission>
  <gazebo reference="waist_lidar">
<implicitSpringDamper>1</implicitSpringDamper>
  </gazebo>
  <gazebo>
<plugin filename="libgazebo_ros_control.so" name="gazebo_ros_control">
<robotNamespace>thor_mang</robotNamespace>
</plugin>
  </gazebo>
</robot>
