<?xml version="1.0" ?>
<!-- =================================================================================== -->
<!-- |    This document was autogenerated by xacro from bigman.urdf.xacro              | -->
<!-- |    EDITING THIS FILE BY HAND IS NOT RECOMMENDED                                 | -->
<!-- =================================================================================== -->
<robot name="bigman" xmlns:xacro="http://ros.org/wiki/xacro">
  <!-- 
  ROS urdf definition of the BIGMAN humanoid robot by Istituto Italiano di Tecnologia
  
  DO NOT INCLUDE THIS FILE DIRECTLY! USE bigman_robot.urdf.xacro INSTEAD!

  Author: Enrico Mingo & Alessio Rocchi

  Inertial matrix has to be in CoM frame (URDF specs)

  Velocity and effort limits are fake!
-->
  <!-- ************ MODEL CONFIGURATION ************ -->
  <!--
####################################################
##
##  BIGMAN_UPPER_BODY
##  if "true" the kinematic chains of the arms and torso 
##  will be used to generate the model
##
####################################################
-->
  <!--
####################################################
##
##  BIGMAN_LEGS
##  if "true" the kinematic chains of the legs
##  will be used to generate the model
##
####################################################
-->
  <!--
####################################################
##
##  BIGMAN_OLD_CHEST
##  if "true" the old version of the chest will be
##  used.
##  
##
####################################################
-->
  <!--
####################################################
##
##  BIGMAN_FIXED_HANDS
##  if "true" a fixed joint between wrist and hand 
##  will be used otherwise a rotative joints will
##  be used.
##  
##
####################################################
-->
  <!--
####################################################
##
##  BIGMAN_FIXED_MULTISENSE
##  if "true" a fixed joint between "head" and 
##  "hokuyo_link" will be used otherwise a continuous 
##  joints will be used.
##  
##
####################################################
-->
  <!--
####################################################
##
##  BIGMAN_HEAD
##  if "true" a fixed joint between "NeckPitch" and
##  "head" will be used to connect the head to the rest
##  of the body. If "false" the head will not be added 
##  to the model (this is the case when the multisense
##  from the launch file is used). 
##  
##
####################################################
-->
  <!--
####################################################
##
##  BIGMAN_ADD_PROTECTIONS
##  if "true" the protections are added to the model.
##  
##
####################################################
-->
  <!--
####################################################
##
##  BIGMAN_ADD_BACKPACK
##  if "true" the backpack is added to the model.
##  
##
####################################################
-->
  <!--
####################################################
##
##  BIGMAN_ADD_RAISING_SUPPORT
##  if "true" the raising support are added to the model.
##  
##
####################################################
-->
  <!--
####################################################
##
##  BIGMAN_NEW_FEET
##  if "true" the new feet with the joint in the middle
##  are used to the model.
##  
##
####################################################
-->
  <!--
####################################################
##
##  BIGMAN_SAFETY_JOINT_LIMITS_X
##  if "true" the more strict joint limits are used 
##  for the X part
##  
##
####################################################
-->
  <!-- ***********  MODEL COLORS *********** -->
  <material name="grey">
    <color rgba="0.5 0.5 0.5 1"/>
  </material>
  <material name="dark_grey">
    <color rgba="0.3 0.3 0.3 1"/>
  </material>
  <material name="blue">
    <color rgba="0.0 0.2 0.3 1"/>
  </material>
  <!-- ************ BIGMAN BASE ************** -->
  <!-- 
  ROS urdf definition of the BIGMAN humanoid robot by Istituto Italiano di Tecnologia
  
  DO NOT INCLUDE THIS FILE DIRECTLY! USE bigman_robot.urdf.xacro INSTEAD!

  Author: Enrico Mingo & Alessio Rocchi

  Inertial matrix has to be in CoM frame (URDF specs)

  Velocity and effort limits are fake!
-->
  <!--
The coordinate frame called base_link is rigidly attached to the robot root body. It is recommended to choose the robot waist as its root body. The base_link can be attached to the root in any arbitrary position or orientation; for every hardware platform there will be a different place on the base that provides an obvious point of reference. Note that REP 103 [1] specifies a preferred orientation for frames. -->
<!--  <link name="base_link"/> -->
  <link name="Waist">
    <inertial>
      <origin rpy="0.0 0.0 0.0" xyz="-0.022813402 -0.00073935443 0.030422909"/>
      <mass value="1.1046081e+01"/>
      <inertia ixx="0.096207978" ixy="0.00014081043" ixz="0.0031258127" iyy="0.098511158" iyz="0.00013938149" izz="0.086541531"/>
    </inertial>
    <visual>
      <origin rpy="0 0 0" xyz="0 0 0"/>
      <geometry name="Waist_visual">
        <mesh filename="package://bigman_urdf/meshes/Waist.STL" scale="0.001 0.001 0.001"/>
      </geometry>
      <material name="grey"/>
    </visual>
    <collision>
      <origin rpy="0 0 0" xyz="0 0 0"/>
      <geometry name="Waist_collision">
        <mesh filename="package://bigman_urdf/meshes/simple/Waist.STL" scale="0.001 0.001 0.001"/>
      </geometry>
    </collision>
  </link>
<!--  <joint name="base_joint" type="fixed">
    <parent link="base_link"/>
    <child link="Waist"/>
    <origin rpy="0 0 0" xyz="0 0 0"/>
  </joint> -->
  <!-- ********************TORSO******************** -->
  <!-- first real link of the robot, inertial reference frame -->
  <!-- Scale factor for meshes -->
  <!-- LINKS -->
  <!-- This links are defined in order to be compliant with http://www.ros.org/reps/rep-0120.html#coordinate-frames
and to define the end effectors of the robot-->
  <!-- The coordinate frame called torso is attached to the lowest body of the model which is a parent of l_gripper, r_gripper and gaze. -->
  <link name="torso"/>
  <link name="DWL">
    <inertial>
      <origin rpy="0 0 0" xyz="-0.04610869 0.02232230 -0.02249514"/>
      <mass value="1.44965471"/>
      <inertia ixx="0.01096760" ixy="0.00111556" ixz="0.00030030" iyy="0.00409572" iyz="0.00054456" izz="0.01143795"/>
    </inertial>
    <visual>
      <origin rpy="0 0 0" xyz="0.0 0.0 0.0"/>
      <geometry name="DWL_visual">
        <mesh filename="package://bigman_urdf/meshes/TorsoRoll.STL" scale="0.001 0.001 0.001"/>
      </geometry>
      <material name="dark_grey"/>
    </visual>
    <collision>
      <origin rpy="0 0 0" xyz="0.0 0.0 0.0"/>
      <geometry name="DWL_collision">
        <mesh filename="package://bigman_urdf/meshes/simple/TorsoRoll.STL" scale="0.001 0.001 0.001"/>
      </geometry>
    </collision>
  </link>
  <link name="DWS">
    <inertial>
      <origin rpy="0 0 0" xyz="0.00010203 0.00928164 0.08113610"/>
      <mass value="5.28825567"/>
      <inertia ixx="0.01628069" ixy="-0.00000323" ixz="0.00001424" iyy="0.01424286" iyz="0.00075458" izz="0.00994169"/>
    </inertial>
    <visual>
      <origin rpy="0 0 0" xyz="0.0 0.0 0.0"/>
      <geometry name="DWS_visual">
        <mesh filename="package://bigman_urdf/meshes/TorsoYawPitch.STL" scale="0.001 0.001 0.001"/>
      </geometry>
      <material name="dark_grey"/>
    </visual>
    <collision>
      <origin rpy="0 0 0" xyz="0.0 0.0 0.0"/>
      <geometry name="DWS_collision">
        <mesh filename="package://bigman_urdf/meshes/simple/TorsoYawPitch.STL" scale="0.001 0.001 0.001"/>
      </geometry>
    </collision>
  </link>
  <link name="DWYTorso">
    <inertial>
      <origin rpy="0 0 0" xyz="0.0 0.00 0.3"/>
      <mass value="26"/>
      <inertia ixx="0.18629757" ixy="0.00008160" ixz="0.00030250" iyy="0.02013829" iyz="-0.00001790" izz="0.18850541"/>
    </inertial>
    <visual>
      <origin rpy="0 0 0" xyz="0.0 0.0 0.0"/>
      <geometry name="DWYTorso_visual">
        <mesh filename="package://bigman_urdf/meshes/NewChest.STL" scale="0.001 0.001 0.001"/>
      </geometry>
      <material name="blue"/>
    </visual>
    <collision>
      <origin rpy="0 0 0" xyz="0.0 0.0 0.0"/>
      <geometry name="DWYTorso_collision">
        <mesh filename="package://bigman_urdf/meshes/simple/NewChest.STL" scale="0.001 0.001 0.001"/>
      </geometry>
    </collision>
  </link>
  <!-- UPDATE DATA FOR TORSO PROTECTION! -->
  <link name="TorsoProtections">
    <inertial>
      <origin rpy="0 0 0" xyz="-0.082963193 7.0747291e-07 0.075409106"/>
      <mass value="4.7"/>
      <inertia ixx="0.14773769" ixy="0.0" ixz="-0.029780072" iyy="0.16085511" iyz="0.0" izz="0.15409381"/>
    </inertial>
    <visual>
      <origin rpy="0 0 0" xyz="0.0 0.0 0.0"/>
      <geometry name="TorsoProtections_visual">
        <mesh filename="package://bigman_urdf/meshes/ProtectionSystem.STL" scale="0.001 0.001 0.001"/>
      </geometry>
      <material name="dark_grey"/>
    </visual>
    <collision>
      <origin rpy="0 0 0" xyz="0.0 0.0 0.0"/>
      <geometry name="TorsoProtections_collision">
        <mesh filename="package://bigman_urdf/meshes/simple/ProtectionSystem.STL" scale="0.001 0.001 0.001"/>
      </geometry>
    </collision>
  </link>
  <!-- UPDATE DATA FOR TORSO PROTECTION! -->
  <link name="backpack">
    <inertial>
      <origin rpy="0 0 0" xyz="0 0 -0.065"/>
      <mass value="10.0"/>
      <inertia ixx="0.0890833333333" ixy="0.0" ixz="0.0" iyy="0.0354166666667" iyz="0.0" izz="0.0963333333333"/>
    </inertial>
    <visual>
      <origin rpy="0 0 0" xyz="0.0 0.0 0.0"/>
      <geometry name="backpack_visual">
        <box size="0.16 0.3 0.22"/>
      </geometry>
      <material name="dark_grey"/>
    </visual>
    <collision>
      <origin rpy="0 0 0" xyz="0.0 0.0 0.0"/>
      <geometry name="backpack_collision">
        <box size="0.16 0.3 0.22"/>
      </geometry>
    </collision>
  </link>
  <!-- JOINTS -->
  <joint name="backpack_joint" type="fixed">
    <parent link="DWYTorso"/>
    <child link="backpack"/>
    <origin rpy="0 0 0" xyz="-0.185 0 -0.025"/>
  </joint>
  <joint name="torso_protection_joint" type="fixed">
    <parent link="DWYTorso"/>
    <child link="TorsoProtections"/>
    <origin rpy="0 0 0" xyz="0.0 0 0.0"/>
  </joint>
  <joint name="torso_joint" type="fixed">
    <parent link="DWYTorso"/>
    <child link="torso"/>
    <origin rpy="0 0 0" xyz="0.0 0 0.0"/>
  </joint>
  <joint name="WaistLat" type="revolute">
    <parent link="Waist"/>
    <child link="DWL"/>
    <origin rpy="0 0 0" xyz="0.1115 0 0.195982"/>
    <axis xyz="0.89879991307 0 0.43835911792"/>
    <limit effort="120" lower="-0.610865238196" upper="0.610865238196" velocity="6.283"/>
    <dynamics damping="3.0" friction="0"/>
  </joint>
  <joint name="WaistSag" type="revolute">
    <parent link="DWL"/>
    <child link="DWS"/>
    <origin rpy="0 0 0" xyz="0 0 0"/>
    <axis xyz="0 1 0"/>
    <limit effort="220" lower="-0.349065850398" upper="1.39626340159" velocity="6.283"/>
    <dynamics damping="3.0" friction="0"/>
  </joint>
  <joint name="WaistYaw" type="revolute">
    <parent link="DWS"/>
    <child link="DWYTorso"/>
    <origin rpy="0 0 0" xyz="0 0 0.22275"/>
    <axis xyz="0 0 1"/>
    <limit effort="120" lower="-2.84488668074" upper="2.84488668074" velocity="6.283"/>
    <dynamics damping="3.0" friction="0"/>
  </joint>
  <!-- ********************NECK********************* -->
  <!-- LINKS -->
  <link name="NeckYaw">
    <inertial>
      <origin rpy="0 0 0" xyz="0.0 0.0 0.1155"/>
      <mass value="0.35"/>
      <inertia ixx="0.00032840119" ixy="0.0" ixz="0.0" iyy="7.0371675e-05" iyz="0.0" izz="0.00032840111"/>
    </inertial>
    <visual>
      <origin rpy="0 0 0" xyz="0.0 0.0 0.0"/>
      <geometry name="NeckYaw_visual">
        <mesh filename="package://bigman_urdf/meshes/NeckYaw.STL" scale="0.001 0.001 0.001"/>
      </geometry>
      <material name="grey"/>
    </visual>
    <collision>
      <origin rpy="0 0 0" xyz="0.0 0.0 0.0"/>
      <geometry name="NeckYaw_collision">
        <mesh filename="package://bigman_urdf/meshes/simple/NeckYaw.STL" scale="0.001 0.001 0.001"/>
      </geometry>
    </collision>
  </link>
  <link name="NeckPitch">
    <inertial>
      <origin rpy="0 0 0" xyz="-0.102 0.0 0.26575"/>
      <mass value="0.623"/>
      <inertia ixx="0.0010388333" ixy="0.0" ixz="0.0" iyy="0.00054689381" iyz="0.0" izz="0.00054689381"/>
    </inertial>
    <visual>
      <origin rpy="0 0 0" xyz="0.0 0.0 0.0"/>
      <geometry name="NeckPitch_visual">
        <mesh filename="package://bigman_urdf/meshes/NeckPitch.STL" scale="0.001 0.001 0.001"/>
      </geometry>
      <material name="grey"/>
    </visual>
    <collision>
      <origin rpy="0 0 0" xyz="0.0 0.0 0.0"/>
      <geometry name="NeckPitch_collision">
        <mesh filename="package://bigman_urdf/meshes/simple/NeckPitch.STL" scale="0.001 0.001 0.001"/>
      </geometry>
    </collision>
  </link>
  <!-- JOINTS -->
  <joint name="NeckYawj" type="revolute">
    <parent link="DWYTorso"/>
    <child link="NeckYaw"/>
    <origin rpy="0 0 0" xyz="0 0 0"/>
    <axis xyz="0 0 1"/>
    <!--     <limit velocity="6.283" effort="120" lower="${(-175.0)*toRad}" upper="${(175.0)*toRad}" /> -->
    <limit effort="120" lower="-0.610865238196" upper="0.610865238196" velocity="6.283"/>
    <dynamics damping="3.0" friction="0"/>
  </joint>
  <joint name="NeckPitchj" type="revolute">
    <parent link="NeckYaw"/>
    <child link="NeckPitch"/>
    <origin rpy="0 0 0" xyz="0 0 0.1155"/>
    <axis xyz="0 1 0"/>
    <!--limit velocity="6.283" effort="120" lower="${(-30.0)*toRad}" upper="${(70.0)*toRad}" /-->
    <limit effort="120" lower="-0.261799387798" upper="1.04719755119" velocity="6.283"/>
    <dynamics damping="3.0" friction="0"/>
  </joint>
  <!-- ********************LEGS******************** -->
  <!-- This links are defined in order to be compliant with http://www.ros.org/reps/rep-0120.html#coordinate-frames
	and to define the end effectors of the robot -->
  <!--  position and orientation of the leg regardless of the support body geometry -->
  <link name="l_ankle"/>
  <link name="r_ankle"/>
  <!-- position and orientation of the left leg support body. The (X,Y) plane of this frame must be coplanar with the support body contact surface. It is recommended to choose the origin as the projection of the support body origin on the contact surface. The Z coordinate of this frame should be on the ground level when standing. -->
  <link name="l_sole"/>
  <link name="r_sole"/>
  <!--  position and orientation of the leg toe body. The (X,Y) plan of this frame must be coplanar with the toe body contact surface. It is recommended to choose the origin as the projection of the body center on the contact surface. -->
  <link name="l_toe"/>
  <link name="r_toe"/>
  <!-- LINKS -->
  <!-- ********************RIGHT LEG******************** -->
  <link name="RHipMot">
    <inertial>
      <origin rpy="0 0 0" xyz="-0.10348188 -0.10919813 -0.064924056"/>
      <mass value="3.7958197"/>
      <inertia ixx="0.015639017" ixy="0.0018504661" ixz="0.0023907793" iyy="0.023519749" iyz="-0.0023303162" izz="0.020953643"/>
    </inertial>
    <visual>
      <origin rpy="0 0 0" xyz="0 0 0"/>
      <geometry name="RHipMot_visual">
        <mesh filename="package://bigman_urdf/meshes/HipRoll.STL" scale="0.001 0.001 0.001"/>
      </geometry>
      <material name="dark_grey"/>
    </visual>
    <collision>
      <origin rpy="0 0 0" xyz="0 0 0"/>
      <geometry name="RHipMot_collision">
        <mesh filename="package://bigman_urdf/meshes/simple/HipRoll.STL" scale="0.001 0.001 0.001"/>
      </geometry>
    </collision>
  </link>
  <link name="RThighUpLeg">
    <inertial>
      <origin rpy="0 0 0" xyz="-0.0052929709 -0.022561833 0.0056701669"/>
      <mass value="3.2402068"/>
      <inertia ixx="0.010102097" ixy="0.00010858487" ixz="0.00025291395" iyy="0.0067147" iyz="8.3447072e-05" izz="0.01048513"/>
    </inertial>
    <visual>
      <origin rpy="0 0 0" xyz="0 0 0"/>
      <geometry name="RThighUpLeg_visual">
        <mesh filename="package://bigman_urdf/meshes/HipYaw.STL" scale="0.001 0.001 0.001"/>
      </geometry>
      <material name="dark_grey"/>
    </visual>
    <collision>
      <origin rpy="0 0 0" xyz="0 0 0"/>
      <geometry name="RThighUpLeg_collision">
        <mesh filename="package://bigman_urdf/meshes/simple/HipYaw.STL" scale="0.001 0.001 0.001"/>
      </geometry>
    </collision>
  </link>
  <link name="RThighLowLeg">
    <inertial>
      <origin rpy="0 0 0" xyz="0.037746286 -0.028539939 -0.19310133"/>
      <mass value="5.0950736"/>
      <inertia ixx="0.051607858" ixy="0.0022253472" ixz="0.002452979" iyy="0.044349153" iyz="-0.0041006942" izz="0.023374453"/>
    </inertial>
    <visual>
      <origin rpy="0 0 0" xyz="0 0 0"/>
      <geometry name="RThighLowLeg_visual">
        <mesh filename="package://bigman_urdf/meshes/HipPitch.STL" scale="0.001 0.001 0.001"/>
      </geometry>
      <material name="grey"/>
    </visual>
    <collision>
      <origin rpy="0 0 0" xyz="0 0 0"/>
      <geometry name="RThighLowLeg_collision">
        <mesh filename="package://bigman_urdf/meshes/simple/HipPitch.STL" scale="0.001 0.001 0.001"/>
      </geometry>
    </collision>
  </link>
  <link name="RLowLeg">
    <inertial>
      <origin rpy="0 0 0" xyz="-0.0050828668 0.0037732093 -0.072605017"/>
      <mass value="5.6495309"/>
      <inertia ixx="0.10535542" ixy="-0.00058199221" ixz="0.0016743598" iyy="0.097857796" iyz="-0.0033770181" izz="0.020854086"/>
    </inertial>
    <visual>
      <origin rpy="0 0 0" xyz="0 0 0"/>
      <geometry name="RLowLeg_visual">
        <mesh filename="package://bigman_urdf/meshes/KneePitchCalf.STL" scale="0.001 0.001 0.001"/>
      </geometry>
      <material name="dark_grey"/>
    </visual>
    <collision>
      <origin rpy="0 0 0" xyz="0 0 0"/>
      <geometry name="RLowLeg_collision">
        <mesh filename="package://bigman_urdf/meshes/simple/KneePitchCalf.STL" scale="0.001 0.001 0.001"/>
      </geometry>
    </collision>
  </link>
  <link name="RFootmot">
    <inertial>
      <origin rpy="0 0 0" xyz="-0.022024173 0.0025677238 0.00094588455"/>
      <mass value="3.2844159"/>
      <inertia ixx="0.0075550679" ixy="0.00067488292" ixz="5.8332889e-05" iyy="0.011241163" iyz="-0.00014552081" izz="0.013391865"/>
    </inertial>
    <visual>
      <origin rpy="0 0 0" xyz="0 0 0"/>
      <geometry name="RFootmot_visual">
        <mesh filename="package://bigman_urdf/meshes/AnklePitch.STL" scale="0.001 0.001 0.001"/>
      </geometry>
      <material name="dark_grey"/>
    </visual>
    <collision>
      <origin rpy="0 0 0" xyz="0 0 0"/>
      <geometry name="RFootmot_collision">
        <mesh filename="package://bigman_urdf/meshes/simple/AnklePitch.STL" scale="0.001 0.001 0.001"/>
      </geometry>
    </collision>
  </link>
  <link name="RFoot">
    <inertial>
      <origin rpy="0 0 0" xyz="-0.00653584 -0.00479384 -0.10180375"/>
      <mass value="3.42638110"/>
      <inertia ixx="0.01032886" ixy="-0.00016407" ixz="-0.00201294" iyy="0.02854025" iyz="0.00046315" izz="0.02799499"/>
    </inertial>
    <visual>
      <origin rpy="0 0 0" xyz="0 0 0"/>
      <geometry name="RFoot_visual">
        <mesh filename="package://bigman_urdf/meshes/NewFoot.STL" scale="0.001 0.001 0.001"/>
      </geometry>
      <material name="dark_grey"/>
    </visual>
    <collision>
      <!--<origin xyz="0 0 0" rpy="0 0 0"/>
      <geometry name="RFoot_collision">
        <mesh filename="package://bigman_urdf/meshes/simple/Foot.STL" scale="0.001 -0.001 0.001"/>
      </geometry>-->
      <origin rpy="0 0 0" xyz="0.005 -0.01 -0.1359"/>
      <geometry>
        <box size="0.32 0.16 0.015"/>
      </geometry>
    </collision>
  </link>
  <!-- ********************LEFT LEG******************** -->
  <link name="LHipMot">
    <inertial>
      <origin rpy="0 0 0" xyz="-0.10348188 0.10919813 -0.064924056"/>
      <mass value="3.7958197"/>
      <inertia ixx="0.015639017" ixy="-0.0018504661" ixz="0.0023907793" iyy="0.023519749" iyz="0.0023303162" izz="0.020953643"/>
    </inertial>
    <visual>
      <origin rpy="0 0 0" xyz="0 0 0"/>
      <geometry name="LHipMot_visual">
        <mesh filename="package://bigman_urdf/meshes/HipRoll.STL" scale="0.001 -0.001 0.001"/>
      </geometry>
      <material name="dark_grey"/>
    </visual>
    <collision>
      <origin rpy="0 0 0" xyz="0 0 0"/>
      <geometry name="LHipMot_collision">
        <mesh filename="package://bigman_urdf/meshes/simple/HipRoll.STL" scale="0.001 -0.001 0.001"/>
      </geometry>
    </collision>
  </link>
  <link name="LThighUpLeg">
    <inertial>
      <origin rpy="0 0 0" xyz="-0.0052929709 0.022561833 0.0056701669"/>
      <mass value="3.2402068"/>
      <inertia ixx="0.010102097" ixy="-0.00010858487" ixz="0.00025291395" iyy="0.0067147" iyz="-8.3447072e-05" izz="0.01048513"/>
    </inertial>
    <visual>
      <origin rpy="0 0 0" xyz="0 0 0"/>
      <geometry name="LThighUpLeg_visual">
        <mesh filename="package://bigman_urdf/meshes/HipYaw.STL" scale="0.001 -0.001 0.001"/>
      </geometry>
      <material name="dark_grey"/>
    </visual>
    <collision>
      <origin rpy="0 0 0" xyz="0 0 0"/>
      <geometry name="LThighUpLeg_collision">
        <mesh filename="package://bigman_urdf/meshes/simple/HipYaw.STL" scale="0.001 -0.001 0.001"/>
      </geometry>
    </collision>
  </link>
  <link name="LThighLowLeg">
    <inertial>
      <origin rpy="0 0 0" xyz="0.037746286 0.028539939 -0.19310133"/>
      <mass value="5.0950736"/>
      <inertia ixx="0.051607858" ixy="-0.0022253472" ixz="0.002452979" iyy="0.044349153" iyz="0.0041006942" izz="0.023374453"/>
    </inertial>
    <visual>
      <origin rpy="0 0 0" xyz="0 0 0"/>
      <geometry name="LThighLowLeg_visual">
        <mesh filename="package://bigman_urdf/meshes/HipPitch.STL" scale="0.001 -0.001 0.001"/>
      </geometry>
      <material name="grey"/>
    </visual>
    <collision>
      <origin rpy="0 0 0" xyz="0 0 0"/>
      <geometry name="LThighLowLeg_collision">
        <mesh filename="package://bigman_urdf/meshes/simple/HipPitch.STL" scale="0.001 -0.001 0.001"/>
      </geometry>
    </collision>
  </link>
  <link name="LLowLeg">
    <inertial>
      <origin rpy="0 0 0" xyz="-0.0050828668 -0.0037732093 -0.072605017"/>
      <mass value="5.6495309"/>
      <inertia ixx="0.10535542" ixy="0.00058199221" ixz="0.0016743598" iyy="0.097857796" iyz="0.0033770181" izz="0.020854086"/>
    </inertial>
    <visual>
      <origin rpy="0 0 0" xyz="0 0 0"/>
      <geometry name="LLowLeg_visual">
        <mesh filename="package://bigman_urdf/meshes/KneePitchCalf.STL" scale="0.001 -0.001 0.001"/>
      </geometry>
      <material name="dark_grey"/>
    </visual>
    <collision>
      <origin rpy="0 0 0" xyz="0 0 0"/>
      <geometry name="LLowLeg_collision">
        <mesh filename="package://bigman_urdf/meshes/simple/KneePitchCalf.STL" scale="0.001 -0.001 0.001"/>
      </geometry>
    </collision>
  </link>
  <link name="LFootmot">
    <inertial>
      <origin rpy="0 0 0" xyz="-0.022024173 -0.0025677238 0.00094588455"/>
      <mass value="3.2844159"/>
      <inertia ixx="0.0075550679" ixy="-0.00067488292" ixz="5.8332889e-05" iyy="0.011241163" iyz="0.00014552081" izz="0.013391865"/>
    </inertial>
    <visual>
      <origin rpy="0 0 0" xyz="0 0 0"/>
      <geometry name="LFootmot_visual">
        <mesh filename="package://bigman_urdf/meshes/AnklePitch.STL" scale="0.001 -0.001 0.001"/>
      </geometry>
      <material name="dark_grey"/>
    </visual>
    <collision>
      <origin rpy="0 0 0" xyz="0 0 0"/>
      <geometry name="LFootmot_collision">
        <mesh filename="package://bigman_urdf/meshes/simple/AnklePitch.STL" scale="0.001 -0.001 0.001"/>
      </geometry>
    </collision>
  </link>
  <link name="LFoot">
    <inertial>
      <origin rpy="0 0 0" xyz="-0.00653584 0.00479384 -0.10180375"/>
      <mass value="3.42638110"/>
      <inertia ixx="0.01032886" ixy="-0.00016407" ixz="-0.00201294" iyy="0.02854025" iyz="0.00046315" izz="0.02799499"/>
    </inertial>
    <visual>
      <origin rpy="0 0 0" xyz="0 0 0"/>
      <geometry name="LFoot_visual">
        <mesh filename="package://bigman_urdf/meshes/NewFoot.STL" scale="0.001 -0.001 0.001"/>
      </geometry>
      <material name="dark_grey"/>
    </visual>
    <collision>
      <!--
      <origin xyz="0 0 0" rpy="0 0 0"/>
      <geometry name="LFoot_collision">
        <mesh filename="package://bigman_urdf/meshes/simple/Foot.STL" scale="0.001 0.001 0.001"/>
      </geometry>
      -->
      <origin rpy="0 0 0" xyz="0.005 0.01 -0.1359"/>
      <geometry>
        <box size="0.32 0.16 0.015"/>
      </geometry>
    </collision>
  </link>
  <!-- JOINTS -->
  <!-- ********************RIGHT LEG******************** -->
  <joint name="RHipLat" type="revolute">
    <parent link="Waist"/>
    <child link="RHipMot"/>
    <origin rpy="0 0 0" xyz="0.1059 -0.06 0.0"/>
    <axis xyz="1 0 0"/>
    <limit effort="220" lower="-0.87222" upper="0.697778" velocity="6.283"/>
    <dynamics damping="3.0" friction="0"/>
  </joint>
  <joint name="RHipYaw" type="revolute">
    <parent link="RHipMot"/>
    <child link="RThighUpLeg"/>
    <origin rpy="0 0 0" xyz="-0.0889 -0.121032 -0.217872"/>
    <axis xyz="0 0 1"/>
    <limit effort="120" lower="-1.57" upper="0.872222" velocity="6.283"/>
    <dynamics damping="3.0" friction="0"/>
  </joint>
  <joint name="RHipSag" type="revolute">
    <parent link="RThighUpLeg"/>
    <child link="RThighLowLeg"/>
    <origin rpy="0 0 0" xyz="0.0 0.0 0.0"/>
    <axis xyz="0 1 0"/>
    <limit effort="220" lower="-2.09333" upper="1.046667" velocity="6.283"/>
    <dynamics damping="3.0" friction="0"/>
  </joint>
  <joint name="RKneeSag" type="revolute">
    <parent link="RThighLowLeg"/>
    <child link="RLowLeg"/>
    <origin rpy="0 0 0" xyz="0.0 0.0 -0.356"/>
    <axis xyz="0 1 0"/>
    <limit effort="220" lower="0.0" upper="2.442222" velocity="6.283"/>
    <dynamics damping="3.0" friction="0"/>
  </joint>
  <joint name="RAnkSag" type="revolute">
    <parent link="RLowLeg"/>
    <child link="RFootmot"/>
    <origin rpy="0 0 0" xyz="0.0 0.0 -0.4"/>
    <axis xyz="0 1 0"/>
    <limit effort="220" lower="-1.39556" upper="0.697778" velocity="6.283"/>
    <dynamics damping="3.0" friction="0"/>
  </joint>
  <joint name="RAnkLat" type="revolute">
    <parent link="RFootmot"/>
    <child link="RFoot"/>
    <origin rpy="0 0 0" xyz="0.0 0.0 0.0"/>
    <axis xyz="1 0 0"/>
    <limit effort="120" lower="-0.785" upper="0.785" velocity="6.283"/>
    <dynamics damping="3.0" friction="0"/>
  </joint>
  <!-- ********************LEFT LEG******************** -->
  <joint name="LHipLat" type="revolute">
    <parent link="Waist"/>
    <child link="LHipMot"/>
    <origin rpy="0 0 0" xyz="0.1059 0.06 0.0"/>
    <axis xyz="1 0 0"/>
    <limit effort="220" lower="-0.697778" upper="0.87222" velocity="6.283"/>
    <dynamics damping="3.0" friction="0"/>
  </joint>
  <joint name="LHipYaw" type="revolute">
    <parent link="LHipMot"/>
    <child link="LThighUpLeg"/>
    <origin rpy="0 0 0" xyz="-0.0889 0.121032 -0.217872"/>
    <axis xyz="0 0 1"/>
    <limit effort="120" lower="-0.872222" upper="1.57" velocity="6.283"/>
    <dynamics damping="3.0" friction="0"/>
  </joint>
  <joint name="LHipSag" type="revolute">
    <parent link="LThighUpLeg"/>
    <child link="LThighLowLeg"/>
    <origin rpy="0 0 0" xyz="0.0 0.0 0.0"/>
    <axis xyz="0 1 0"/>
    <limit effort="220" lower="-2.09333" upper="1.046667" velocity="6.283"/>
    <dynamics damping="3.0" friction="0"/>
  </joint>
  <joint name="LKneeSag" type="revolute">
    <parent link="LThighLowLeg"/>
    <child link="LLowLeg"/>
    <origin rpy="0 0 0" xyz="0.0 0.0 -0.356"/>
    <axis xyz="0 1 0"/>
    <limit effort="220" lower="0.0" upper="2.442222" velocity="6.283"/>
    <dynamics damping="3.0" friction="0"/>
  </joint>
  <joint name="LAnkSag" type="revolute">
    <parent link="LLowLeg"/>
    <child link="LFootmot"/>
    <origin rpy="0 0 0" xyz="0.0 0.0 -0.4"/>
    <axis xyz="0 1 0"/>
    <limit effort="220" lower="-1.39556" upper="0.697778" velocity="6.283"/>
    <dynamics damping="3.0" friction="0"/>
  </joint>
  <joint name="LAnkLat" type="revolute">
    <parent link="LFootmot"/>
    <child link="LFoot"/>
    <origin rpy="0 0 0" xyz="0.0 0.0 0.0"/>
    <axis xyz="1 0 0"/>
    <limit effort="120" lower="-0.785" upper="0.785" velocity="6.283"/>
    <dynamics damping="3.0" friction="0"/>
  </joint>
  <joint name="l_ankle_joint" type="fixed">
    <parent link="LFoot"/>
    <child link="l_ankle"/>
    <origin rpy="0 0 0" xyz="0 0 0"/>
  </joint>
  <joint name="r_ankle_joint" type="fixed">
    <parent link="RFoot"/>
    <child link="r_ankle"/>
    <origin rpy="0 0 0" xyz="0 0 0"/>
  </joint>
  <joint name="l_sole_joint" type="fixed">
    <parent link="LFoot"/>
    <child link="l_sole"/>
    <origin rpy="0 0 0" xyz="0 0 -0.1435"/>
  </joint>
  <joint name="r_sole_joint" type="fixed">
    <parent link="RFoot"/>
    <child link="r_sole"/>
    <origin rpy="0 0 0" xyz="0 0 -0.1435"/>
  </joint>
  <joint name="l_toe_joint" type="fixed">
    <parent link="l_sole"/>
    <child link="l_toe"/>
    <origin rpy="0 0 0" xyz="0.16 0 0"/>
  </joint>
  <joint name="r_toe_joint" type="fixed">
    <parent link="r_sole"/>
    <child link="r_toe"/>
    <origin rpy="0 0 0" xyz="0.16 0 0"/>
  </joint>
  <!-- Reference frames in feet -->
  <!-- macro for reference frames in foot -->
  <!-- macro for one reference frame in foot -->
  <link name="l_foot_upper_right_link"/>
  <joint name="l_foot_upper_right_joint" type="fixed">
    <origin rpy="0 0 0" xyz="0.16 -0.07 0"/>
    <parent link="l_sole"/>
    <child link="l_foot_upper_right_link"/>
  </joint>
  <!-- macro for one reference frame in foot -->
  <link name="l_foot_upper_left_link"/>
  <joint name="l_foot_upper_left_joint" type="fixed">
    <origin rpy="0 0 0" xyz="0.16 0.09 0"/>
    <parent link="l_sole"/>
    <child link="l_foot_upper_left_link"/>
  </joint>
  <!-- macro for one reference frame in foot -->
  <link name="l_foot_lower_right_link"/>
  <joint name="l_foot_lower_right_joint" type="fixed">
    <origin rpy="0 0 0" xyz="-0.16 -0.07 0"/>
    <parent link="l_sole"/>
    <child link="l_foot_lower_right_link"/>
  </joint>
  <!-- macro for one reference frame in foot -->
  <link name="l_foot_lower_left_link"/>
  <joint name="l_foot_lower_left_joint" type="fixed">
    <origin rpy="0 0 0" xyz="-0.16 0.09 0"/>
    <parent link="l_sole"/>
    <child link="l_foot_lower_left_link"/>
  </joint>
  <!-- macro for reference frames in foot -->
  <!-- macro for one reference frame in foot -->
  <link name="r_foot_upper_right_link"/>
  <joint name="r_foot_upper_right_joint" type="fixed">
    <origin rpy="0 0 0" xyz="0.16 0.07 0"/>
    <parent link="r_sole"/>
    <child link="r_foot_upper_right_link"/>
  </joint>
  <!-- macro for one reference frame in foot -->
  <link name="r_foot_upper_left_link"/>
  <joint name="r_foot_upper_left_joint" type="fixed">
    <origin rpy="0 0 0" xyz="0.16 -0.09 0"/>
    <parent link="r_sole"/>
    <child link="r_foot_upper_left_link"/>
  </joint>
  <!-- macro for one reference frame in foot -->
  <link name="r_foot_lower_right_link"/>
  <joint name="r_foot_lower_right_joint" type="fixed">
    <origin rpy="0 0 0" xyz="-0.16 0.07 0"/>
    <parent link="r_sole"/>
    <child link="r_foot_lower_right_link"/>
  </joint>
  <!-- macro for one reference frame in foot -->
  <link name="r_foot_lower_left_link"/>
  <joint name="r_foot_lower_left_joint" type="fixed">
    <origin rpy="0 0 0" xyz="-0.16 -0.09 0"/>
    <parent link="r_sole"/>
    <child link="r_foot_lower_left_link"/>
  </joint>
  <!-- ********************ARMS******************** -->
  <!-- LINKS -->
  <!-- RIGHT ARM -->
  <link name="RShp">
    <inertial>
      <origin rpy="0 0 0" xyz="-0.00543349 -0.04480023 0.01581062"/>
      <mass value="1.81745527"/>
      <inertia ixx="0.00571053" ixy="0.00041083" ixz="-0.00005130" iyy="0.01126908" iyz="-0.00003461" izz="0.01371197"/>
    </inertial>
    <visual>
      <origin rpy="0 0 0" xyz="0 0 0"/>
      <geometry name="RShp_visual">
        <mesh filename="package://bigman_urdf/meshes/ShoulderPitch.STL" scale="0.001 0.001 0.001"/>
      </geometry>
      <material name="dark_grey"/>
    </visual>
    <collision>
      <origin rpy="0 0 0" xyz="0 0 0"/>
      <geometry name="RShp_collision">
        <mesh filename="package://bigman_urdf/meshes/simple/ShoulderPitch.STL" scale="0.001 0.001 0.001"/>
      </geometry>
    </collision>
  </link>
  <link name="RShr">
    <inertial>
      <origin rpy="0 0 0" xyz="0.00729315 0.00002698 -0.07529696"/>
      <mass value="5.00486460"/>
      <inertia ixx="0.01644345" ixy="-0.00001187" ixz="-0.00010546" iyy="0.01804804" iyz="-0.00000565" izz="0.00802420"/>
    </inertial>
    <visual>
      <origin rpy="0 0 0" xyz="0 0 0"/>
      <geometry name="RShr_visual">
        <mesh filename="package://bigman_urdf/meshes/TopUpperArm.STL" scale="0.001 0.001 0.001"/>
      </geometry>
      <material name="dark_grey"/>
    </visual>
    <collision>
      <origin rpy="0 0 0" xyz="0 0 0"/>
      <geometry name="RShr_collision">
        <mesh filename="package://bigman_urdf/meshes/simple/TopUpperArm.STL" scale="0.001 0.001 0.001"/>
      </geometry>
    </collision>
  </link>
  <link name="RShy">
    <inertial>
      <origin rpy="0 0 0" xyz="0.02765373 -0.03258647 -0.12698781"/>
      <mass value="3.20289133"/>
      <inertia ixx="0.01129046" ixy="0.00013518" ixz="-0.00134760" iyy="0.00984951" iyz="-0.00026836" izz="0.00728549"/>
    </inertial>
    <visual>
      <origin rpy="0 0 0" xyz="0 0 0"/>
      <geometry name="RShy_visual">
        <mesh filename="package://bigman_urdf/meshes/BottomUpperArm.STL" scale="0.001 0.001 0.001"/>
      </geometry>
      <material name="dark_grey"/>
    </visual>
    <collision>
      <origin rpy="0 0 0" xyz="0 0 0"/>
      <geometry name="RShy_collision">
        <mesh filename="package://bigman_urdf/meshes/simple/BottomUpperArm.STL" scale="0.001 0.001 0.001"/>
      </geometry>
    </collision>
  </link>
  <link name="RElb">
    <inertial>
      <origin rpy="0 0 0" xyz="-0.055754915 -0.007582604 -0.043820396"/>
      <mass value="8.6765385e-01"/>
      <inertia ixx="0.0040395238" ixy="0.00034973136" ixz="-0.00068400465" iyy="0.0022460561" iyz="0.00028844444" izz="0.0044895027"/>
    </inertial>
    <visual>
      <origin rpy="0 0 0" xyz="0 0 0"/>
      <geometry name="RElb_visual">
        <mesh filename="package://bigman_urdf/meshes/Elbow.STL" scale="0.001 0.001 0.001"/>
      </geometry>
      <material name="dark_grey"/>
    </visual>
    <collision>
      <origin rpy="0 0 0" xyz="0 0 0"/>
      <geometry name="RElb_collision">
        <mesh filename="package://bigman_urdf/meshes/simple/Elbow.STL" scale="0.001 0.001 0.001"/>
      </geometry>
    </collision>
  </link>
  <!-- LEFT ARM -->
  <link name="LShp">
    <inertial>
      <origin rpy="0 0 0" xyz="-0.00543349 0.04480023 0.01581062"/>
      <mass value="1.81745527"/>
      <inertia ixx="0.00571053" ixy="-0.00041083" ixz="-0.00005130" iyy="0.01126908" iyz="0.00003461" izz="0.01371197"/>
    </inertial>
    <visual>
      <origin rpy="0 0 0" xyz="0 0 0"/>
      <geometry name="LShp_visual">
        <mesh filename="package://bigman_urdf/meshes/ShoulderPitch.STL" scale="0.001 -0.001 0.001"/>
      </geometry>
      <material name="dark_grey"/>
    </visual>
    <collision>
      <origin rpy="0 0 0" xyz="0 0 0"/>
      <geometry name="LShp_collision">
        <mesh filename="package://bigman_urdf/meshes/simple/ShoulderPitch.STL" scale="0.001 -0.001 0.001"/>
      </geometry>
    </collision>
  </link>
  <link name="LShr">
    <inertial>
      <origin rpy="0 0 0" xyz="0.00729315 -0.00002698 -0.07529696"/>
      <mass value="5.00486460"/>
      <inertia ixx="0.01644345" ixy="0.00001187" ixz="-0.00010546" iyy="0.01804804" iyz="0.00000565" izz="0.00802420"/>
    </inertial>
    <visual>
      <origin rpy="0 0 0" xyz="0 0 0"/>
      <geometry name="LShr_visual">
        <mesh filename="package://bigman_urdf/meshes/TopUpperArm.STL" scale="0.001 -0.001 0.001"/>
      </geometry>
      <material name="dark_grey"/>
    </visual>
    <collision>
      <origin rpy="0 0 0" xyz="0 0 0"/>
      <geometry name="LShr_collision">
        <mesh filename="package://bigman_urdf/meshes/simple/TopUpperArm.STL" scale="0.001 -0.001 0.001"/>
      </geometry>
    </collision>
  </link>
  <link name="LShy">
    <inertial>
      <origin rpy="0 0 0" xyz="0.02765373 0.03258647 -0.12698781"/>
      <mass value="3.20289133"/>
      <inertia ixx="0.01129046" ixy="-0.00013518" ixz="-0.00134760" iyy="0.00984951" iyz="0.00026836" izz="0.00728549"/>
    </inertial>
    <visual>
      <origin rpy="0 0 0" xyz="0 0 0"/>
      <geometry name="LShy_visual">
        <mesh filename="package://bigman_urdf/meshes/BottomUpperArm.STL" scale="0.001 -0.001 0.001"/>
      </geometry>
      <material name="dark_grey"/>
    </visual>
    <collision>
      <origin rpy="0 0 0" xyz="0 0 0"/>
      <geometry name="LShy_collision">
        <mesh filename="package://bigman_urdf/meshes/simple/BottomUpperArm.STL" scale="0.001 -0.001 0.001"/>
      </geometry>
    </collision>
  </link>
  <link name="LElb">
    <inertial>
      <origin rpy="0 0 0" xyz="-0.055754915 0.007582604 -0.043820396"/>
      <mass value="8.6765385e-01"/>
      <inertia ixx="0.0040395238" ixy="-0.00034973136" ixz="-0.00068400465" iyy="0.0022460561" iyz="-0.00028844444" izz="0.0044895027"/>
    </inertial>
    <visual>
      <origin rpy="0 0 0" xyz="0 0 0"/>
      <geometry name="LElb_visual">
        <mesh filename="package://bigman_urdf/meshes/Elbow.STL" scale="0.001 -0.001 0.001"/>
      </geometry>
      <material name="dark_grey"/>
    </visual>
    <collision>
      <origin rpy="0 0 0" xyz="0 0 0"/>
      <geometry name="LElb_collision">
        <mesh filename="package://bigman_urdf/meshes/simple/Elbow.STL" scale="0.001 -0.001 0.001"/>
      </geometry>
    </collision>
  </link>
  <!-- JOINTS -->
  <!-- RIGHT ARM -->
  <joint name="RShSag" type="revolute">
    <parent link="DWYTorso"/>
    <child link="RShp"/>
    <origin rpy="0 0 0.3491" xyz="0.045646 -0.219164 0.001531"/>
    <axis xyz="0 0.743144825 -0.669130606"/>
    <limit effort="120" lower="-2.84488668074" upper="2.8099800957" velocity="6.283"/>
    <dynamics damping="3.0" friction="0"/>
  </joint>
  <joint name="RShLat" type="revolute">
    <parent link="RShp"/>
    <child link="RShr"/>
    <origin rpy="0 0 0" xyz="0.0 -0.116568264 0.03364"/>
    <axis xyz="1 0 0"/>
    <limit effort="120" lower="-3.8571776469" upper="-0.122173047639" velocity="6.283"/>
    <dynamics damping="3.0" friction="0"/>
  </joint>
  <joint name="RShYaw" type="revolute">
    <parent link="RShr"/>
    <child link="RShy"/>
    <origin rpy="0 0 0" xyz="0.0 0.0 -0.222"/>
    <axis xyz="0 0 1"/>
    <limit effort="120" lower="-2.86233997326" upper="2.82743338822" velocity="6.283"/>
    <dynamics damping="3.0" friction="0"/>
  </joint>
  <joint name="RElbj" type="revolute">
    <parent link="RShy"/>
    <child link="RElb"/>
    <origin rpy="0 0 0" xyz="0.036 0.0 -0.15"/>
    <axis xyz="0 1 0"/>
    <limit effort="60" lower="-2.96705972838" upper="0.593411945677" velocity="6.283"/>
    <dynamics damping="3.0" friction="0"/>
  </joint>
  <!-- LEFT ARM -->
  <joint name="LShSag" type="revolute">
    <parent link="DWYTorso"/>
    <child link="LShp"/>
    <origin rpy="0 0 -0.3491" xyz="0.045646 0.219164 0.001531"/>
    <axis xyz="0.0 0.743144825 0.669130606"/>
    <limit effort="120" lower="-2.87979326578" upper="2.79252680318" velocity="6.283"/>
    <dynamics damping="3.0" friction="0"/>
  </joint>
  <joint name="LShLat" type="revolute">
    <parent link="LShp"/>
    <child link="LShr"/>
    <origin rpy="0 0 0" xyz="0.0 0.116568264 0.03364"/>
    <axis xyz="1 0 0"/>
    <limit effort="120" lower="0.0872664625995" upper="3.8571776469" velocity="6.283"/>
    <dynamics damping="3.0" friction="0"/>
  </joint>
  <joint name="LShYaw" type="revolute">
    <parent link="LShr"/>
    <child link="LShy"/>
    <origin rpy="0 0 0" xyz="0.0 0.0 -0.222"/>
    <axis xyz="0 0 1"/>
    <limit effort="120" lower="-2.84488668074" upper="2.84488668074" velocity="6.283"/>
    <dynamics damping="3.0" friction="0"/>
  </joint>
  <joint name="LElbj" type="revolute">
    <parent link="LShy"/>
    <child link="LElb"/>
    <origin rpy="0 0 0" xyz="0.036 0.0 -0.15"/>
    <axis xyz="0 1 0"/>
    <limit effort="60" lower="-2.96705972838" upper="0.593411945677" velocity="6.283"/>
    <dynamics damping="3.0" friction="0"/>
  </joint>
  <!-- ***** LEGS F/T SENSOR REF FRAMES *******-->
  <link name="l_leg_ft"/>
  <link name="r_leg_ft"/>
  <joint name="l_leg_ft_joint" type="fixed">
    <parent link="LFoot"/>
    <child link="l_leg_ft"/>
    <origin rpy="0 0 0" xyz="0.005 0 -0.107"/>
  </joint>
  <joint name="r_leg_ft_joint" type="fixed">
    <parent link="RFoot"/>
    <child link="r_leg_ft"/>
    <origin rpy="0 0 0" xyz="0.005 0 -0.107"/>
  </joint>
  <link name="l_arm_ft"/>
  <link name="r_arm_ft"/>
  <joint name="l_arm_ft_joint" type="fixed">
    <parent link="LWrMot3"/>
    <child link="l_arm_ft"/>
    <origin rpy="0 0 0" xyz="0 0 -0.0565"/>
  </joint>
  <joint name="r_arm_ft_joint" type="fixed">
    <parent link="RWrMot3"/>
    <child link="r_arm_ft"/>
    <origin rpy="0 0 0" xyz="0 0 -0.0565"/>
  </joint>
  <!-- ************ FOREARMS ************ -->
  <!-- This links are defined in order to be compliant with http://www.ros.org/reps/rep-0120.html#coordinate-frames
	and to define the end effectors of the robot -->
  <!-- position and orientation of the arm regardless of the tool (grasping device for instance) attached to it -->
  <link name="l_wrist"/>
  <link name="r_wrist"/>
  <!-- ****************LINKS**************** -->
  <!-- ****************LEFT FOREARM**************** -->
  <link name="LForearm">
    <inertial>
      <origin rpy="0 0 0" xyz="1.2625599e-05 0.0042975381 0.044717986"/>
      <mass value="2.2127686"/>
      <inertia ixx="0.0065428368" ixy="-4.1196967e-05" ixz="3.272727e-06" iyy="0.005587829" iyz="0.00042088668" izz="0.0024783023"/>
    </inertial>
    <visual>
      <origin rpy="0 0 0" xyz="0 0 0"/>
      <geometry name="LForearm_visual">
        <mesh filename="package://bigman_urdf/meshes/Forearm.STL" scale="0.001 -0.001 0.001"/>
      </geometry>
      <material name="dark_grey"/>
    </visual>
    <collision>
      <origin rpy="0 0 0" xyz="0 0 0"/>
      <geometry name="LForearm_collision">
        <mesh filename="package://bigman_urdf/meshes/simple/Forearm.STL" scale="0.001 -0.001 0.001"/>
      </geometry>
    </collision>
  </link>
  <link name="LWrMot2">
    <inertial>
      <origin rpy="0 0 0" xyz="0.009819377 0.0013797184 -0.080380065"/>
      <mass value="1.2838072"/>
      <inertia ixx="0.001994124" ixy="2.569706e-05" ixz="0.00017443538" iyy="0.0021755329" iyz="-0.00012100987" izz="0.001830376"/>
    </inertial>
    <visual>
      <origin rpy="0 0 0" xyz="0 0 0"/>
      <geometry name="LWrMot2_visual">
        <mesh filename="package://bigman_urdf/meshes/ForearmPitch.STL" scale="0.001 -0.001 0.001"/>
      </geometry>
      <material name="dark_grey"/>
    </visual>
    <collision>
      <origin rpy="0 0 0" xyz="0 0 0"/>
      <geometry name="LWrMot2_collision">
        <mesh filename="package://bigman_urdf/meshes/simple/ForearmPitch.STL" scale="0.001 -0.001 0.001"/>
      </geometry>
    </collision>
  </link>
  <link name="LWrMot3">
    <inertial>
      <origin rpy="0 0 0" xyz="0.0070380706 -1.0811188e-05 -0.039669274"/>
      <mass value="4.2801447e-01"/>
      <inertia ixx="0.00028620156" ixy="5.2570457e-08" ixz="-3.9174213e-05" iyy="0.00071261855" iyz="-9.5020266e-08" izz="0.00061444258"/>
    </inertial>
    <visual>
      <origin rpy="0 0 0" xyz="0 0 0"/>
      <geometry name="LWrMot3_visual">
        <mesh filename="package://bigman_urdf/meshes/ForearmRoll.STL" scale="0.001 -0.001 0.001"/>
      </geometry>
      <material name="blue"/>
    </visual>
    <collision>
      <origin rpy="0 0 0" xyz="0 0 0"/>
      <geometry name="LWrMot3_collision">
        <mesh filename="package://bigman_urdf/meshes/simple/ForearmRoll.STL" scale="0.001 -0.001 0.001"/>
      </geometry>
    </collision>
  </link>
  <!-- ****************RIGHT FOREARM**************** -->
  <link name="RForearm">
    <inertial>
      <origin rpy="0 0 0" xyz="1.2625599e-05 -0.0042975381 0.044717986"/>
      <mass value="2.2127686"/>
      <inertia ixx="0.0065428368" ixy="4.1196967e-05" ixz="3.272727e-06" iyy="0.005587829" iyz="-0.00042088668" izz="0.0024783023"/>
    </inertial>
    <visual>
      <origin rpy="0 0 0" xyz="0 0 0"/>
      <geometry name="RForearm_visual">
        <mesh filename="package://bigman_urdf/meshes/Forearm.STL" scale="0.001 0.001 0.001"/>
      </geometry>
      <material name="dark_grey"/>
    </visual>
    <collision>
      <origin rpy="0 0 0" xyz="0 0 0"/>
      <geometry name="RForearm_collision">
        <mesh filename="package://bigman_urdf/meshes/simple/Forearm.STL" scale="0.001 0.001 0.001"/>
      </geometry>
    </collision>
  </link>
  <link name="RWrMot2">
    <inertial>
      <origin rpy="0 0 0" xyz="0.009819377 -0.0013797184 -0.080380065"/>
      <mass value="1.2838072"/>
      <inertia ixx="0.001994124" ixy="-2.569706e-05" ixz="0.00017443538" iyy="0.0021755329" iyz="0.00012100987" izz="0.001830376"/>
    </inertial>
    <visual>
      <origin rpy="0 0 0" xyz="0 0 0"/>
      <geometry name="RWrMot2_visual">
        <mesh filename="package://bigman_urdf/meshes/ForearmPitch.STL" scale="0.001 0.001 0.001"/>
      </geometry>
      <material name="dark_grey"/>
    </visual>
    <collision>
      <origin rpy="0 0 0" xyz="0 0 0"/>
      <geometry name="RWrMot2_collision">
        <mesh filename="package://bigman_urdf/meshes/simple/ForearmPitch.STL" scale="0.001 0.001 0.001"/>
      </geometry>
    </collision>
  </link>
  <link name="RWrMot3">
    <inertial>
      <origin rpy="0 0 0" xyz="0.0070380706 1.0811188e-05 -0.039669274"/>
      <mass value="4.2801447e-01"/>
      <inertia ixx="0.00028620156" ixy="-5.2570457e-08" ixz="-3.9174213e-05" iyy="0.00071261855" iyz="9.5020266e-08" izz="0.00061444258"/>
    </inertial>
    <visual>
      <origin rpy="0 0 0" xyz="0 0 0"/>
      <geometry name="RWrMot3_visual">
        <mesh filename="package://bigman_urdf/meshes/ForearmRoll.STL" scale="0.001 0.001 0.001"/>
      </geometry>
      <material name="blue"/>
    </visual>
    <collision>
      <origin rpy="0 0 0" xyz="0 0 0"/>
      <geometry name="RWrMot3_collision">
        <mesh filename="package://bigman_urdf/meshes/simple/ForearmRoll.STL" scale="0.001 0.001 0.001"/>
      </geometry>
    </collision>
  </link>
  <!-- ****************JOINTS**************** -->
  <!-- ****************LEFT FOREARM**************** -->
  <joint name="LForearmPlate" type="revolute">
    <parent link="LElb"/>
    <child link="LForearm"/>
    <origin rpy="0 0 0" xyz="-0.075 0.0 -0.1955"/>
    <axis xyz="0 0 1"/>
    <limit effort="60" lower="-2.529" upper="2.529" velocity="6.283"/>
    <dynamics damping="0.03" friction="0"/>
  </joint>
  <joint name="LWrj1" type="revolute">
    <parent link="LForearm"/>
    <child link="LWrMot2"/>
    <origin rpy="0 0 0" xyz="0 0 0"/>
    <axis xyz="0 1 0"/>
    <limit effort="60" lower="-1.48" upper="1.48" velocity="6.283"/>
    <dynamics damping="0.03" friction="0"/>
  </joint>
  <joint name="LWrj2" type="revolute">
    <parent link="LWrMot2"/>
    <child link="LWrMot3"/>
    <origin rpy="0 0 0" xyz="0 0 -0.092"/>
    <axis xyz="1 0 0"/>
    <limit effort="60" lower="-1.48" upper="1.48" velocity="6.283"/>
    <dynamics damping="0.03" friction="0"/>
  </joint>
  <joint name="l_wrist_joint" type="fixed">
    <parent link="LWrMot3"/>
    <child link="l_wrist"/>
    <origin rpy="0 0 0" xyz="0 0 0"/>
  </joint>
  <!-- ****************RIGHT FOREARM**************** -->
  <joint name="RForearmPlate" type="revolute">
    <parent link="RElb"/>
    <child link="RForearm"/>
    <origin rpy="0 0 0" xyz="-0.075 0.0 -0.1955"/>
    <axis xyz="0 0 1"/>
    <limit effort="60" lower="-2.529" upper="2.529" velocity="6.283"/>
    <dynamics damping="0.03" friction="0"/>
  </joint>
  <joint name="RWrj1" type="revolute">
    <parent link="RForearm"/>
    <child link="RWrMot2"/>
    <origin rpy="0 0 0" xyz="0 0 0"/>
    <axis xyz="0 1 0"/>
    <limit effort="60" lower="-1.48" upper="1.48" velocity="6.283"/>
    <dynamics damping="0.03" friction="0"/>
  </joint>
  <joint name="RWrj2" type="revolute">
    <parent link="RWrMot2"/>
    <child link="RWrMot3"/>
    <origin rpy="0 0 0" xyz="0 0 -0.092"/>
    <axis xyz="1 0 0"/>
    <limit effort="60" lower="-1.48" upper="1.48" velocity="6.283"/>
    <dynamics damping="0.03" friction="0"/>
  </joint>
  <joint name="r_wrist_joint" type="fixed">
    <parent link="RWrMot3"/>
    <child link="r_wrist"/>
    <origin rpy="0 0 0" xyz="0 0 0"/>
  </joint>
  <!-- ************ HANDS ************ -->
  <!-- For the hand we use the inertia of a parallelepiped -->
  <!-- LINKS -->
  <link name="RSoftHand"/>
  <link name="RSoftHandLink">
    <inertial>
      <origin rpy="0 0 0" xyz="0 0 -0.17"/>
      <mass value="1.2"/>
      <inertia ixx="0.00232" ixy="0" ixz="0" iyy="0.00296" iyz="0" izz="0.00136"/>
    </inertial>
    <visual>
      <origin rpy="0.0 0.0 0.0" xyz="0.0 0.0 0.0"/>
      <geometry name="RSoftHandLink_visual">
        <mesh filename="package://bigman_urdf/meshes/SoftHandOpen.STL" scale="0.001 0.001 0.001"/>
      </geometry>
      <material name="grey"/>
    </visual>
    <collision>
      <origin rpy="0.0 0.0 0.0" xyz="0.0 0.0 0.0"/>
      <geometry name="RSoftHandLink_collision">
        <mesh filename="package://bigman_urdf/meshes/simple/SoftHandOpen.STL" scale="0.001 0.001 0.001"/>
      </geometry>
    </collision>
  </link>
  <link name="LSoftHand"/>
  <link name="LSoftHandLink">
    <inertial>
      <origin rpy="0 0 0" xyz="0 0 -0.17"/>
      <mass value="1.2"/>
      <inertia ixx="0.00232" ixy="0" ixz="0" iyy="0.00296" iyz="0" izz="0.00136"/>
    </inertial>
    <visual>
      <origin rpy="0.0 0.0 0.0" xyz="0.0 0.0 0.0"/>
      <geometry name="LSoftHandLink_visual">
        <mesh filename="package://bigman_urdf/meshes/SoftHandOpen.STL" scale="0.001 -0.001 0.001"/>
      </geometry>
      <material name="grey"/>
    </visual>
    <collision>
      <origin rpy="0.0 0.0 0.0" xyz="0.0 0.0 0.0"/>
      <geometry name="LSoftHandLink_collision">
        <mesh filename="package://bigman_urdf/meshes/simple/SoftHandOpen.STL" scale="0.001 -0.001 0.001"/>
      </geometry>
    </collision>
  </link>
  <!-- JOINTS -->
  <joint name="r_handj" type="fixed">
    <parent link="RWrMot3"/>
    <child link="RSoftHandLink"/>
    <origin rpy="0 0 0" xyz="0 0 0"/>
  </joint>
  <joint name="r_handj2" type="fixed">
    <parent link="RSoftHandLink"/>
    <child link="RSoftHand"/>
    <origin rpy="0 0 0" xyz="0 0.0305 -0.21"/>
  </joint>
  <joint name="l_handj" type="fixed">
    <parent link="LWrMot3"/>
    <child link="LSoftHandLink"/>
    <origin rpy="0 0 0" xyz="0 0 0"/>
  </joint>
  <joint name="l_handj2" type="fixed">
    <parent link="LSoftHandLink"/>
    <child link="LSoftHand"/>
    <origin rpy="0 0 0" xyz="0 -0.0305 -0.21"/>
  </joint>
  <!-- multisense_sl_v4 with fixed joints (NOT FOR SIMULATION) -->
  <!-- IMU -->
  <link name="imu_link">
    <inertial>
      <mass value="0.01"/>
      <origin xyz="0 0 0"/>
      <inertia ixx="1.0E-6" ixy="0" ixz="0" iyy="1.0E-6" iyz="0" izz="1.0E-6"/>
    </inertial>
    <visual>
      <origin rpy="0 0 0" xyz="0 0 0"/>
      <geometry>
        <box size="0.01 0.01 0.01"/>
      </geometry>
    </visual>
  </link>
  <link name="imu_link2">
    <inertial>
      <mass value="0.01"/>
      <origin xyz="0 0 0"/>
      <inertia ixx="1.0E-6" ixy="0" ixz="0" iyy="1.0E-6" iyz="0" izz="1.0E-6"/>
    </inertial>
    <visual>
      <origin rpy="0 0 0" xyz="0 0 0"/>
      <geometry>
        <box size="0.01 0.01 0.01"/>
      </geometry>
    </visual>
  </link>
  <joint name="imu_joint" type="fixed">
    <parent link="Waist"/>
    <child link="imu_link"/>
    <origin rpy="0 0 0" xyz="0.0535 0.0 0.0601"/>
  </joint>
  <joint name="imu_joint2" type="fixed">
    <parent link="Waist"/>
    <child link="imu_link2"/>
    <origin rpy="0 0 0" xyz="0.0135 0.0 0.0601"/>
  </joint>
</robot>

